[Tue Jul 21 20:23:54.531808 2020] [wsgi:error] [pid 14543] [client 175.193.7.139:10602] Daemon process called 'unqocninitapi' cannot be accessed by this WSGI application: /home/django/backend/unqocninitapi/wsgi.py
[Tue Jul 21 20:24:33.280797 2020] [wsgi:error] [pid 14545] [client 175.193.7.139:10603] Daemon process called 'unqocninitapi' cannot be accessed by this WSGI application: /home/django/backend/unqocninitapi/wsgi.py
[Tue Jul 21 20:25:09.974488 2020] [wsgi:error] [pid 14646] [client 175.193.7.139:10639] Daemon process called 'unqocninitapi' cannot be accessed by this WSGI application: /home/django/backend/unqocninitapi/wsgi.py
[Tue Jul 21 20:27:22.277571 2020] [wsgi:error] [pid 14806] [remote 175.193.7.139:10731] Not Found: /
Exception ignored in: <function BaseEventLoop.__del__ at 0x7f0bbbab5670>
Traceback (most recent call last):
  File "/usr/lib/python3.8/asyncio/base_events.py", line 654, in __del__
NameError: name 'ResourceWarning' is not defined
Exception ignored in: <function Local.__del__ at 0x7f0bc0702700>
Traceback (most recent call last):
  File "/home/django/unqocn_venv/lib/python3.8/site-packages/asgiref/local.py", line 96, in __del__
NameError: name 'TypeError' is not defined
Exception ignored in: <function Local.__del__ at 0x7f0bc0702700>
Traceback (most recent call last):
  File "/home/django/unqocn_venv/lib/python3.8/site-packages/asgiref/local.py", line 96, in __del__
NameError: name 'TypeError' is not defined
Exception ignored in: <function Local.__del__ at 0x7f0bc0702700>
Traceback (most recent call last):
  File "/home/django/unqocn_venv/lib/python3.8/site-packages/asgiref/local.py", line 96, in __del__
NameError: name 'TypeError' is not defined
