[Tue Jul 21 20:27:29.214297 2020] [wsgi:error] [pid 14805] [remote 175.193.7.139:10737] Not Found: /index.php
[Tue Jul 21 20:27:40.648532 2020] [wsgi:error] [pid 14805] [remote 175.193.7.139:10736] Not Found: /index.php
[Tue Jul 21 20:27:46.878884 2020] [wsgi:error] [pid 14805] [remote 175.193.7.139:10743] Not Found: /index.php
[Tue Jul 21 20:39:47.680022 2020] [wsgi:error] [pid 14805] [remote 175.193.7.139:11131] Not Found: /index.php
Exception ignored in: <function BaseEventLoop.__del__ at 0x7f0bbbab5670>
Traceback (most recent call last):
  File "/usr/lib/python3.8/asyncio/base_events.py", line 654, in __del__
NameError: name 'ResourceWarning' is not defined
Exception ignored in: <function Local.__del__ at 0x7f0bc0702700>
Traceback (most recent call last):
  File "/home/django/unqocn_venv/lib/python3.8/site-packages/asgiref/local.py", line 96, in __del__
NameError: name 'TypeError' is not defined
Exception ignored in: <function Local.__del__ at 0x7f0bc0702700>
Traceback (most recent call last):
  File "/home/django/unqocn_venv/lib/python3.8/site-packages/asgiref/local.py", line 96, in __del__
NameError: name 'TypeError' is not defined
Exception ignored in: <function Local.__del__ at 0x7f0bc0702700>
Traceback (most recent call last):
  File "/home/django/unqocn_venv/lib/python3.8/site-packages/asgiref/local.py", line 96, in __del__
NameError: name 'TypeError' is not defined
[Tue Jul 21 20:45:15.115553 2020] [wsgi:error] [pid 15466] [remote 65.154.226.109:16850] Not Found: /
Exception ignored in: <function Local.__del__ at 0x7f0bc080f700>
Traceback (most recent call last):
  File "/home/django/unqocn_venv/lib/python3.8/site-packages/asgiref/local.py", line 96, in __del__
NameError: name 'TypeError' is not defined
Exception ignored in: <function Local.__del__ at 0x7f0bc080f700>
Traceback (most recent call last):
  File "/home/django/unqocn_venv/lib/python3.8/site-packages/asgiref/local.py", line 96, in __del__
NameError: name 'TypeError' is not defined
[Tue Jul 21 20:46:22.849857 2020] [wsgi:error] [pid 15578] [remote 65.154.226.109:39943] Not Found: /
Exception ignored in: <function Local.__del__ at 0x7f0bc080f700>
Traceback (most recent call last):
  File "/home/django/unqocn_venv/lib/python3.8/site-packages/asgiref/local.py", line 96, in __del__
NameError: name 'TypeError' is not defined
Exception ignored in: <function Local.__del__ at 0x7f0bc080f700>
Traceback (most recent call last):
  File "/home/django/unqocn_venv/lib/python3.8/site-packages/asgiref/local.py", line 96, in __del__
NameError: name 'TypeError' is not defined
[Tue Jul 21 21:00:11.352456 2020] [wsgi:error] [pid 16738] [remote 185.39.11.105:33804] Not Found: /
[Tue Jul 21 21:04:59.572546 2020] [wsgi:error] [pid 16738] [remote 106.251.88.102:6487] Not Found: /
[Tue Jul 21 21:25:16.345691 2020] [php7:error] [pid 18177] [client 106.102.129.119:39508] script '/var/www/html/index.php' not found or unable to stat, referer: https://unqocn-api.hopto.org/
[Tue Jul 21 21:25:20.872665 2020] [php7:error] [pid 18177] [client 106.102.129.119:39508] script '/var/www/html/index.php' not found or unable to stat, referer: https://unqocn-api.hopto.org/
[Tue Jul 21 21:25:57.225369 2020] [php7:error] [pid 18251] [client 106.102.129.119:6902] script '/var/www/html/index.php' not found or unable to stat, referer: https://unqocn-api.hopto.org/
[Tue Jul 21 21:25:58.864486 2020] [php7:error] [pid 18251] [client 106.102.129.119:6902] script '/var/www/html/index.php' not found or unable to stat
[Tue Jul 21 21:27:41.088340 2020] [wsgi:error] [pid 18448] [remote 106.102.129.119:42660] Not Found: /index.php
[Tue Jul 21 21:27:41.527633 2020] [wsgi:error] [pid 18448] [remote 106.102.129.119:42660] Not Found: /favicon.ico
Exception ignored in: <function Local.__del__ at 0x7f3b391b7700>
Traceback (most recent call last):
  File "/home/django/unqocn_venv/lib/python3.8/site-packages/asgiref/local.py", line 96, in __del__
NameError: name 'TypeError' is not defined
Exception ignored in: <function Local.__del__ at 0x7f3b391b7700>
Traceback (most recent call last):
  File "/home/django/unqocn_venv/lib/python3.8/site-packages/asgiref/local.py", line 96, in __del__
NameError: name 'TypeError' is not defined
[Tue Jul 21 21:28:28.783309 2020] [ssl:warn] [pid 18440] AH01909: unqocn-api.hopto.org:443:0 server certificate does NOT include an ID which matches the server name
[Tue Jul 21 21:28:40.737513 2020] [wsgi:error] [pid 18551] [remote 106.102.129.119:17406] Not Found: /index.php
[Tue Jul 21 21:28:40.962105 2020] [wsgi:error] [pid 18551] [remote 106.102.129.119:17406] Not Found: /favicon.ico
[Tue Jul 21 21:30:01.500841 2020] [wsgi:error] [pid 18551] [remote 185.39.11.105:50016] Not Found: /
Exception ignored in: <function Local.__del__ at 0x7f3b392c4700>
Traceback (most recent call last):
  File "/home/django/unqocn_venv/lib/python3.8/site-packages/asgiref/local.py", line 96, in __del__
NameError: name 'TypeError' is not defined
Exception ignored in: <function Local.__del__ at 0x7f3b392c4700>
Traceback (most recent call last):
  File "/home/django/unqocn_venv/lib/python3.8/site-packages/asgiref/local.py", line 96, in __del__
NameError: name 'TypeError' is not defined
[Tue Jul 21 21:31:01.458762 2020] [wsgi:error] [pid 18751] [remote 106.102.129.119:55352] Not Found: /index.php/login
[Tue Jul 21 21:31:04.838423 2020] [wsgi:error] [pid 18751] [remote 106.102.129.119:55352] Not Found: /index.php
[Tue Jul 21 21:33:35.671112 2020] [wsgi:error] [pid 18751] [remote 106.102.129.119:63477] Not Found: /index.php
Exception ignored in: <function BaseEventLoop.__del__ at 0x7f6952cd9670>
Traceback (most recent call last):
  File "/usr/lib/python3.8/asyncio/base_events.py", line 654, in __del__
NameError: name 'ResourceWarning' is not defined
Exception ignored in: <function Local.__del__ at 0x7f695391e700>
Traceback (most recent call last):
  File "/home/django/unqocn_venv/lib/python3.8/site-packages/asgiref/local.py", line 96, in __del__
NameError: name 'TypeError' is not defined
Exception ignored in: <function Local.__del__ at 0x7f695391e700>
Traceback (most recent call last):
  File "/home/django/unqocn_venv/lib/python3.8/site-packages/asgiref/local.py", line 96, in __del__
NameError: name 'TypeError' is not defined
[Tue Jul 21 21:46:20.438018 2020] [wsgi:error] [pid 19671] [remote 106.102.129.119:48693] Not Found: /
[Tue Jul 21 21:46:20.822827 2020] [wsgi:error] [pid 19671] [remote 106.102.129.119:48693] Not Found: /favicon.ico
[Tue Jul 21 21:54:39.817011 2020] [wsgi:error] [pid 19669] [remote 93.174.93.139:50600] Not Found: /
[Tue Jul 21 22:03:29.635122 2020] [wsgi:error] [pid 19669] [remote 106.102.129.119:27757] Not Found: /index.php
[Tue Jul 21 22:08:43.270958 2020] [wsgi:error] [pid 19669] [remote 93.158.66.48:42370] Not Found: /.git/HEAD
[Tue Jul 21 22:08:44.537059 2020] [wsgi:error] [pid 19669] [remote 93.158.66.48:42538] Not Found: /.git/HEAD
[Tue Jul 21 22:08:46.918306 2020] [wsgi:error] [pid 19669] [remote 93.158.66.43:40428] Not Found: /.git/HEAD
[Tue Jul 21 22:08:48.192798 2020] [wsgi:error] [pid 19669] [remote 93.158.66.43:40656] Not Found: /.git/HEAD
[Tue Jul 21 22:08:48.762212 2020] [wsgi:error] [pid 19669] [remote 93.158.66.45:38826] Not Found: /.git/HEAD
[Tue Jul 21 22:08:50.028841 2020] [wsgi:error] [pid 19669] [remote 93.158.66.45:38994] Not Found: /.git/HEAD
[Tue Jul 21 22:15:15.408395 2020] [wsgi:error] [pid 19669] [remote 93.158.66.49:56048] Not Found: /.git/HEAD
[Tue Jul 21 22:15:16.711332 2020] [wsgi:error] [pid 19669] [remote 93.158.66.49:56266] Not Found: /.git/HEAD
[Tue Jul 21 22:16:20.199181 2020] [wsgi:error] [pid 19669] [remote 93.158.66.43:45010] Not Found: /.git/HEAD
[Tue Jul 21 22:16:21.438287 2020] [wsgi:error] [pid 19669] [remote 93.158.66.43:45468] Not Found: /.git/HEAD
[Tue Jul 21 22:30:38.670447 2020] [wsgi:error] [pid 19669] [remote 62.173.138.154:52951] Not Found: /
[Tue Jul 21 22:52:20.346597 2020] [wsgi:error] [pid 19669] [remote 185.39.11.105:38928] Not Found: /
Exception ignored in: <function BaseEventLoop.__del__ at 0x7f0eef655670>
Traceback (most recent call last):
  File "/usr/lib/python3.8/asyncio/base_events.py", line 654, in __del__
NameError: name 'ResourceWarning' is not defined
Exception ignored in: <function BaseEventLoop.__del__ at 0x7f0eef655670>
Traceback (most recent call last):
  File "/usr/lib/python3.8/asyncio/base_events.py", line 654, in __del__
NameError: name 'ResourceWarning' is not defined
Exception ignored in: <function Local.__del__ at 0x7f0ef429a700>
Traceback (most recent call last):
  File "/home/django/unqocn_venv/lib/python3.8/site-packages/asgiref/local.py", line 96, in __del__
NameError: name 'TypeError' is not defined
Exception ignored in: <function Local.__del__ at 0x7f0ef429a700>
Traceback (most recent call last):
  File "/home/django/unqocn_venv/lib/python3.8/site-packages/asgiref/local.py", line 96, in __del__
NameError: name 'TypeError' is not defined
Exception ignored in: <function Local.__del__ at 0x7f0ef429a700>
Traceback (most recent call last):
  File "/home/django/unqocn_venv/lib/python3.8/site-packages/asgiref/local.py", line 96, in __del__
NameError: name 'TypeError' is not defined
Exception ignored in: <function Local.__del__ at 0x7f0ef429a700>
Traceback (most recent call last):
  File "/home/django/unqocn_venv/lib/python3.8/site-packages/asgiref/local.py", line 96, in __del__
NameError: name 'TypeError' is not defined
Exception ignored in: <function BaseEventLoop.__del__ at 0x7f7601ce0670>
Traceback (most recent call last):
  File "/usr/lib/python3.8/asyncio/base_events.py", line 654, in __del__
NameError: name 'ResourceWarning' is not defined
Exception ignored in: <function Local.__del__ at 0x7f7602925700>
Traceback (most recent call last):
  File "/home/django/unqocn_venv/lib/python3.8/site-packages/asgiref/local.py", line 96, in __del__
NameError: name 'TypeError' is not defined
Exception ignored in: <function Local.__del__ at 0x7f7602925700>
Traceback (most recent call last):
  File "/home/django/unqocn_venv/lib/python3.8/site-packages/asgiref/local.py", line 96, in __del__
NameError: name 'TypeError' is not defined
[Tue Jul 21 23:03:31.138698 2020] [wsgi:error] [pid 2128] [remote 117.111.28.16:31587] Not Found: /
[Tue Jul 21 23:03:31.498904 2020] [wsgi:error] [pid 2128] [remote 117.111.28.16:31587] Not Found: /favicon.ico
Exception ignored in: <function BaseEventLoop.__del__ at 0x7fdc0c11e670>
Traceback (most recent call last):
  File "/usr/lib/python3.8/asyncio/base_events.py", line 654, in __del__
NameError: name 'ResourceWarning' is not defined
Exception ignored in: <function Local.__del__ at 0x7fdc0cd63700>
Traceback (most recent call last):
  File "/home/django/unqocn_venv/lib/python3.8/site-packages/asgiref/local.py", line 96, in __del__
NameError: name 'TypeError' is not defined
Exception ignored in: <function Local.__del__ at 0x7fdc0cd63700>
Traceback (most recent call last):
  File "/home/django/unqocn_venv/lib/python3.8/site-packages/asgiref/local.py", line 96, in __del__
NameError: name 'TypeError' is not defined
Exception ignored in: <function BaseEventLoop.__del__ at 0x7fa662108670>
Traceback (most recent call last):
  File "/usr/lib/python3.8/asyncio/base_events.py", line 654, in __del__
NameError: name 'ResourceWarning' is not defined
Exception ignored in: <function Local.__del__ at 0x7fa662d4d700>
Traceback (most recent call last):
  File "/home/django/unqocn_venv/lib/python3.8/site-packages/asgiref/local.py", line 96, in __del__
NameError: name 'TypeError' is not defined
Exception ignored in: <function Local.__del__ at 0x7fa662d4d700>
Traceback (most recent call last):
  File "/home/django/unqocn_venv/lib/python3.8/site-packages/asgiref/local.py", line 96, in __del__
NameError: name 'TypeError' is not defined
Exception ignored in: <function BaseEventLoop.__del__ at 0x7f264099e670>
Traceback (most recent call last):
  File "/usr/lib/python3.8/asyncio/base_events.py", line 654, in __del__
NameError: name 'ResourceWarning' is not defined
Exception ignored in: <function Local.__del__ at 0x7f26415e3700>
Traceback (most recent call last):
  File "/home/django/unqocn_venv/lib/python3.8/site-packages/asgiref/local.py", line 96, in __del__
NameError: name 'TypeError' is not defined
Exception ignored in: <function Local.__del__ at 0x7f26415e3700>
Traceback (most recent call last):
  File "/home/django/unqocn_venv/lib/python3.8/site-packages/asgiref/local.py", line 96, in __del__
NameError: name 'TypeError' is not defined
[Tue Jul 21 23:17:16.028469 2020] [wsgi:error] [pid 3450] [remote 67.205.165.53:32862] Not Found: /
[Tue Jul 21 23:17:16.242046 2020] [wsgi:error] [pid 3450] [remote 67.205.165.53:32862] Not Found: /
Exception ignored in: <function Local.__del__ at 0x7f26416dc700>
Traceback (most recent call last):
  File "/home/django/unqocn_venv/lib/python3.8/site-packages/asgiref/local.py", line 96, in __del__
NameError: name 'TypeError' is not defined
Exception ignored in: <function Local.__del__ at 0x7f26416dc700>
Traceback (most recent call last):
  File "/home/django/unqocn_venv/lib/python3.8/site-packages/asgiref/local.py", line 96, in __del__
NameError: name 'TypeError' is not defined
[Wed Jul 22 00:01:52.210881 2020] [wsgi:error] [pid 4879] [remote 185.39.11.105:36230] Not Found: /
[Wed Jul 22 00:10:55.235731 2020] [wsgi:error] [pid 4879] [remote 185.39.11.105:32940] Not Found: /
[Wed Jul 22 00:59:01.135592 2020] [wsgi:error] [pid 4881] [remote 80.82.70.187:45115] Not Found: /cache/global/img/gs.gif
[Wed Jul 22 03:32:23.985783 2020] [wsgi:error] [pid 4879] [remote 193.118.53.210:35318] Not Found: /
[Wed Jul 22 04:01:49.895659 2020] [wsgi:error] [pid 4879] [remote 93.174.93.139:55752] Not Found: /
[Wed Jul 22 05:27:15.837233 2020] [wsgi:error] [pid 4879] [remote 185.39.11.105:32872] Not Found: /
[Wed Jul 22 05:47:31.215048 2020] [wsgi:error] [pid 4879] [remote 162.243.128.91:52518] Not Found: /login
[Wed Jul 22 07:04:53.087165 2020] [wsgi:error] [pid 4879] [remote 185.39.11.105:43754] Not Found: /
[Wed Jul 22 08:05:44.352166 2020] [wsgi:error] [pid 4879] [remote 192.35.168.204:53274] Not Found: /
[Wed Jul 22 08:05:45.146211 2020] [wsgi:error] [pid 4879] [remote 192.35.168.204:37872] Not Found: /
[Wed Jul 22 08:28:16.551901 2020] [wsgi:error] [pid 4879] [remote 92.118.161.33:51435] Not Found: /
[Wed Jul 22 10:23:02.954056 2020] [wsgi:error] [pid 4879] [remote 192.168.219.105:2721] Not Found: /etc/intro.asp
[Wed Jul 22 10:23:03.082961 2020] [wsgi:error] [pid 4879] [remote 192.168.219.105:2721] Not Found: /favicon.ico
[Wed Jul 22 10:23:05.726987 2020] [wsgi:error] [pid 4879] [remote 192.168.219.105:2721] Not Found: /
[Wed Jul 22 10:23:11.391928 2020] [wsgi:error] [pid 4881] [remote 192.168.219.105:2731] Not Found: /
[Wed Jul 22 10:23:12.062356 2020] [wsgi:error] [pid 4881] [remote 192.168.219.105:2731] Not Found: /favicon.ico
[Wed Jul 22 10:24:49.041066 2020] [wsgi:error] [pid 4879] [remote 192.168.219.105:2862] Not Found: /
[Wed Jul 22 10:42:02.255639 2020] [wsgi:error] [pid 4881] [remote 80.82.70.187:60650] Not Found: /cache/global/img/gs.gif
[Wed Jul 22 11:13:37.464199 2020] [wsgi:error] [pid 4879] [remote 185.39.11.105:36776] Not Found: /
[Wed Jul 22 12:16:45.683778 2020] [wsgi:error] [pid 4879] [remote 185.39.11.105:56872] Not Found: /
[Wed Jul 22 12:52:53.142012 2020] [wsgi:error] [pid 4879] [remote 216.218.206.69:42416] Not Found: /
Exception ignored in: <function BaseEventLoop.__del__ at 0x7f2640b0e670>
Traceback (most recent call last):
  File "/usr/lib/python3.8/asyncio/base_events.py", line 654, in __del__
NameError: name 'ResourceWarning' is not defined
Exception ignored in: <function Local.__del__ at 0x7f26416dc700>
Traceback (most recent call last):
  File "/home/django/unqocn_venv/lib/python3.8/site-packages/asgiref/local.py", line 96, in __del__
NameError: name 'TypeError' is not defined
Exception ignored in: <function Local.__del__ at 0x7f26416dc700>
Traceback (most recent call last):
  File "/home/django/unqocn_venv/lib/python3.8/site-packages/asgiref/local.py", line 96, in __del__
NameError: name 'TypeError' is not defined
Exception ignored in: <function Local.__del__ at 0x7f26416dc700>
Traceback (most recent call last):
  File "/home/django/unqocn_venv/lib/python3.8/site-packages/asgiref/local.py", line 96, in __del__
NameError: name 'TypeError' is not defined
Exception ignored in: <function Local.__del__ at 0x7f26416dc700>
Traceback (most recent call last):
  File "/home/django/unqocn_venv/lib/python3.8/site-packages/asgiref/local.py", line 96, in __del__
NameError: name 'TypeError' is not defined
Exception ignored in: <function Local.__del__ at 0x7f26416dc700>
Traceback (most recent call last):
  File "/home/django/unqocn_venv/lib/python3.8/site-packages/asgiref/local.py", line 96, in __del__
NameError: name 'TypeError' is not defined
Exception ignored in: <function Local.__del__ at 0x7f2633fa43a0>
Traceback (most recent call last):
  File "/home/django/unqocn_venv/lib/python3.8/site-packages/asgiref/local.py", line 96, in __del__
NameError: name 'TypeError' is not defined
Exception ignored in: <function Local.__del__ at 0x7f2633fa43a0>
Traceback (most recent call last):
  File "/home/django/unqocn_venv/lib/python3.8/site-packages/asgiref/local.py", line 96, in __del__
NameError: name 'TypeError' is not defined
[Wed Jul 22 14:09:01.728152 2020] [wsgi:error] [pid 845] [remote 198.143.133.154:33136] Not Found: /
[Wed Jul 22 15:39:56.648013 2020] [wsgi:error] [pid 845] [remote 221.148.25.236:4076] Internal Server Error: /news/today
[Wed Jul 22 15:39:56.648040 2020] [wsgi:error] [pid 845] [remote 221.148.25.236:4076] Traceback (most recent call last):
[Wed Jul 22 15:39:56.648044 2020] [wsgi:error] [pid 845] [remote 221.148.25.236:4076]   File "/home/django/unqocn_venv/lib/python3.8/site-packages/django/core/handlers/exception.py", line 34, in inner
[Wed Jul 22 15:39:56.648048 2020] [wsgi:error] [pid 845] [remote 221.148.25.236:4076]     response = get_response(request)
[Wed Jul 22 15:39:56.648052 2020] [wsgi:error] [pid 845] [remote 221.148.25.236:4076]   File "/home/django/unqocn_venv/lib/python3.8/site-packages/django/utils/deprecation.py", line 93, in __call__
[Wed Jul 22 15:39:56.648055 2020] [wsgi:error] [pid 845] [remote 221.148.25.236:4076]     response = self.process_request(request)
[Wed Jul 22 15:39:56.648059 2020] [wsgi:error] [pid 845] [remote 221.148.25.236:4076]   File "/home/django/unqocn_venv/lib/python3.8/site-packages/django/middleware/common.py", line 54, in process_request
[Wed Jul 22 15:39:56.648063 2020] [wsgi:error] [pid 845] [remote 221.148.25.236:4076]     path = self.get_full_path_with_slash(request)
[Wed Jul 22 15:39:56.648066 2020] [wsgi:error] [pid 845] [remote 221.148.25.236:4076]   File "/home/django/unqocn_venv/lib/python3.8/site-packages/django/middleware/common.py", line 87, in get_full_path_with_slash
[Wed Jul 22 15:39:56.648070 2020] [wsgi:error] [pid 845] [remote 221.148.25.236:4076]     raise RuntimeError(
[Wed Jul 22 15:39:56.648074 2020] [wsgi:error] [pid 845] [remote 221.148.25.236:4076] RuntimeError: You called this URL via POST, but the URL doesn't end in a slash and you have APPEND_SLASH set. Django can't redirect to the slash URL while maintaining POST data. Change your form to point to unqocn-api.hopto.org/news/today/ (note the trailing slash), or set APPEND_SLASH=False in your Django settings.
[Wed Jul 22 15:40:13.735734 2020] [wsgi:error] [pid 845] [remote 221.148.25.236:4094] Not Found: /favicon.ico
[Wed Jul 22 15:42:02.680783 2020] [wsgi:error] [pid 845] [remote 221.148.25.236:4172] Internal Server Error: /news/today
[Wed Jul 22 15:42:02.680810 2020] [wsgi:error] [pid 845] [remote 221.148.25.236:4172] Traceback (most recent call last):
[Wed Jul 22 15:42:02.680813 2020] [wsgi:error] [pid 845] [remote 221.148.25.236:4172]   File "/home/django/unqocn_venv/lib/python3.8/site-packages/django/core/handlers/exception.py", line 34, in inner
[Wed Jul 22 15:42:02.680816 2020] [wsgi:error] [pid 845] [remote 221.148.25.236:4172]     response = get_response(request)
[Wed Jul 22 15:42:02.680819 2020] [wsgi:error] [pid 845] [remote 221.148.25.236:4172]   File "/home/django/unqocn_venv/lib/python3.8/site-packages/django/utils/deprecation.py", line 93, in __call__
[Wed Jul 22 15:42:02.680822 2020] [wsgi:error] [pid 845] [remote 221.148.25.236:4172]     response = self.process_request(request)
[Wed Jul 22 15:42:02.680824 2020] [wsgi:error] [pid 845] [remote 221.148.25.236:4172]   File "/home/django/unqocn_venv/lib/python3.8/site-packages/django/middleware/common.py", line 54, in process_request
[Wed Jul 22 15:42:02.680836 2020] [wsgi:error] [pid 845] [remote 221.148.25.236:4172]     path = self.get_full_path_with_slash(request)
[Wed Jul 22 15:42:02.680839 2020] [wsgi:error] [pid 845] [remote 221.148.25.236:4172]   File "/home/django/unqocn_venv/lib/python3.8/site-packages/django/middleware/common.py", line 87, in get_full_path_with_slash
[Wed Jul 22 15:42:02.680841 2020] [wsgi:error] [pid 845] [remote 221.148.25.236:4172]     raise RuntimeError(
[Wed Jul 22 15:42:02.680844 2020] [wsgi:error] [pid 845] [remote 221.148.25.236:4172] RuntimeError: You called this URL via POST, but the URL doesn't end in a slash and you have APPEND_SLASH set. Django can't redirect to the slash URL while maintaining POST data. Change your form to point to unqocn-api.hopto.org/news/today/ (note the trailing slash), or set APPEND_SLASH=False in your Django settings.
[Wed Jul 22 15:42:16.487071 2020] [wsgi:error] [pid 845] [remote 221.148.25.236:4180] Internal Server Error: /news/today
[Wed Jul 22 15:42:16.487095 2020] [wsgi:error] [pid 845] [remote 221.148.25.236:4180] Traceback (most recent call last):
[Wed Jul 22 15:42:16.487098 2020] [wsgi:error] [pid 845] [remote 221.148.25.236:4180]   File "/home/django/unqocn_venv/lib/python3.8/site-packages/django/core/handlers/exception.py", line 34, in inner
[Wed Jul 22 15:42:16.487100 2020] [wsgi:error] [pid 845] [remote 221.148.25.236:4180]     response = get_response(request)
[Wed Jul 22 15:42:16.487103 2020] [wsgi:error] [pid 845] [remote 221.148.25.236:4180]   File "/home/django/unqocn_venv/lib/python3.8/site-packages/django/utils/deprecation.py", line 93, in __call__
[Wed Jul 22 15:42:16.487105 2020] [wsgi:error] [pid 845] [remote 221.148.25.236:4180]     response = self.process_request(request)
[Wed Jul 22 15:42:16.487108 2020] [wsgi:error] [pid 845] [remote 221.148.25.236:4180]   File "/home/django/unqocn_venv/lib/python3.8/site-packages/django/middleware/common.py", line 54, in process_request
[Wed Jul 22 15:42:16.487110 2020] [wsgi:error] [pid 845] [remote 221.148.25.236:4180]     path = self.get_full_path_with_slash(request)
[Wed Jul 22 15:42:16.487113 2020] [wsgi:error] [pid 845] [remote 221.148.25.236:4180]   File "/home/django/unqocn_venv/lib/python3.8/site-packages/django/middleware/common.py", line 87, in get_full_path_with_slash
[Wed Jul 22 15:42:16.487115 2020] [wsgi:error] [pid 845] [remote 221.148.25.236:4180]     raise RuntimeError(
[Wed Jul 22 15:42:16.487117 2020] [wsgi:error] [pid 845] [remote 221.148.25.236:4180] RuntimeError: You called this URL via POST, but the URL doesn't end in a slash and you have APPEND_SLASH set. Django can't redirect to the slash URL while maintaining POST data. Change your form to point to unqocn-api.hopto.org/news/today/ (note the trailing slash), or set APPEND_SLASH=False in your Django settings.
[Wed Jul 22 15:42:42.061628 2020] [wsgi:error] [pid 845] [remote 221.148.25.236:4195] Internal Server Error: /news/today
[Wed Jul 22 15:42:42.061654 2020] [wsgi:error] [pid 845] [remote 221.148.25.236:4195] Traceback (most recent call last):
[Wed Jul 22 15:42:42.061657 2020] [wsgi:error] [pid 845] [remote 221.148.25.236:4195]   File "/home/django/unqocn_venv/lib/python3.8/site-packages/django/core/handlers/exception.py", line 34, in inner
[Wed Jul 22 15:42:42.061660 2020] [wsgi:error] [pid 845] [remote 221.148.25.236:4195]     response = get_response(request)
[Wed Jul 22 15:42:42.061663 2020] [wsgi:error] [pid 845] [remote 221.148.25.236:4195]   File "/home/django/unqocn_venv/lib/python3.8/site-packages/django/utils/deprecation.py", line 93, in __call__
[Wed Jul 22 15:42:42.061666 2020] [wsgi:error] [pid 845] [remote 221.148.25.236:4195]     response = self.process_request(request)
[Wed Jul 22 15:42:42.061669 2020] [wsgi:error] [pid 845] [remote 221.148.25.236:4195]   File "/home/django/unqocn_venv/lib/python3.8/site-packages/django/middleware/common.py", line 54, in process_request
[Wed Jul 22 15:42:42.061672 2020] [wsgi:error] [pid 845] [remote 221.148.25.236:4195]     path = self.get_full_path_with_slash(request)
[Wed Jul 22 15:42:42.061683 2020] [wsgi:error] [pid 845] [remote 221.148.25.236:4195]   File "/home/django/unqocn_venv/lib/python3.8/site-packages/django/middleware/common.py", line 87, in get_full_path_with_slash
[Wed Jul 22 15:42:42.061685 2020] [wsgi:error] [pid 845] [remote 221.148.25.236:4195]     raise RuntimeError(
[Wed Jul 22 15:42:42.061688 2020] [wsgi:error] [pid 845] [remote 221.148.25.236:4195] RuntimeError: You called this URL via POST, but the URL doesn't end in a slash and you have APPEND_SLASH set. Django can't redirect to the slash URL while maintaining POST data. Change your form to point to unqocn-api.hopto.org/news/today/ (note the trailing slash), or set APPEND_SLASH=False in your Django settings.
[Wed Jul 22 15:42:53.519656 2020] [wsgi:error] [pid 845] [remote 221.148.25.236:4202] Internal Server Error: /news/today
[Wed Jul 22 15:42:53.519680 2020] [wsgi:error] [pid 845] [remote 221.148.25.236:4202] Traceback (most recent call last):
[Wed Jul 22 15:42:53.519683 2020] [wsgi:error] [pid 845] [remote 221.148.25.236:4202]   File "/home/django/unqocn_venv/lib/python3.8/site-packages/django/core/handlers/exception.py", line 34, in inner
[Wed Jul 22 15:42:53.519685 2020] [wsgi:error] [pid 845] [remote 221.148.25.236:4202]     response = get_response(request)
[Wed Jul 22 15:42:53.519688 2020] [wsgi:error] [pid 845] [remote 221.148.25.236:4202]   File "/home/django/unqocn_venv/lib/python3.8/site-packages/django/utils/deprecation.py", line 93, in __call__
[Wed Jul 22 15:42:53.519690 2020] [wsgi:error] [pid 845] [remote 221.148.25.236:4202]     response = self.process_request(request)
[Wed Jul 22 15:42:53.519693 2020] [wsgi:error] [pid 845] [remote 221.148.25.236:4202]   File "/home/django/unqocn_venv/lib/python3.8/site-packages/django/middleware/common.py", line 54, in process_request
[Wed Jul 22 15:42:53.519695 2020] [wsgi:error] [pid 845] [remote 221.148.25.236:4202]     path = self.get_full_path_with_slash(request)
[Wed Jul 22 15:42:53.519698 2020] [wsgi:error] [pid 845] [remote 221.148.25.236:4202]   File "/home/django/unqocn_venv/lib/python3.8/site-packages/django/middleware/common.py", line 87, in get_full_path_with_slash
[Wed Jul 22 15:42:53.519700 2020] [wsgi:error] [pid 845] [remote 221.148.25.236:4202]     raise RuntimeError(
[Wed Jul 22 15:42:53.519702 2020] [wsgi:error] [pid 845] [remote 221.148.25.236:4202] RuntimeError: You called this URL via POST, but the URL doesn't end in a slash and you have APPEND_SLASH set. Django can't redirect to the slash URL while maintaining POST data. Change your form to point to unqocn-api.hopto.org/news/today/ (note the trailing slash), or set APPEND_SLASH=False in your Django settings.
[Wed Jul 22 15:43:02.431614 2020] [wsgi:error] [pid 845] [remote 221.148.25.236:4207] Internal Server Error: /news/today
[Wed Jul 22 15:43:02.431642 2020] [wsgi:error] [pid 845] [remote 221.148.25.236:4207] Traceback (most recent call last):
[Wed Jul 22 15:43:02.431649 2020] [wsgi:error] [pid 845] [remote 221.148.25.236:4207]   File "/home/django/unqocn_venv/lib/python3.8/site-packages/django/core/handlers/exception.py", line 34, in inner
[Wed Jul 22 15:43:02.431653 2020] [wsgi:error] [pid 845] [remote 221.148.25.236:4207]     response = get_response(request)
[Wed Jul 22 15:43:02.431656 2020] [wsgi:error] [pid 845] [remote 221.148.25.236:4207]   File "/home/django/unqocn_venv/lib/python3.8/site-packages/django/utils/deprecation.py", line 93, in __call__
[Wed Jul 22 15:43:02.431660 2020] [wsgi:error] [pid 845] [remote 221.148.25.236:4207]     response = self.process_request(request)
[Wed Jul 22 15:43:02.431663 2020] [wsgi:error] [pid 845] [remote 221.148.25.236:4207]   File "/home/django/unqocn_venv/lib/python3.8/site-packages/django/middleware/common.py", line 54, in process_request
[Wed Jul 22 15:43:02.431666 2020] [wsgi:error] [pid 845] [remote 221.148.25.236:4207]     path = self.get_full_path_with_slash(request)
[Wed Jul 22 15:43:02.431669 2020] [wsgi:error] [pid 845] [remote 221.148.25.236:4207]   File "/home/django/unqocn_venv/lib/python3.8/site-packages/django/middleware/common.py", line 87, in get_full_path_with_slash
[Wed Jul 22 15:43:02.431679 2020] [wsgi:error] [pid 845] [remote 221.148.25.236:4207]     raise RuntimeError(
[Wed Jul 22 15:43:02.431683 2020] [wsgi:error] [pid 845] [remote 221.148.25.236:4207] RuntimeError: You called this URL via POST, but the URL doesn't end in a slash and you have APPEND_SLASH set. Django can't redirect to the slash URL while maintaining POST data. Change your form to point to unqocn-api.hopto.org/news/today/ (note the trailing slash), or set APPEND_SLASH=False in your Django settings.
[Wed Jul 22 15:43:18.631014 2020] [wsgi:error] [pid 845] [remote 221.148.25.236:4217] Internal Server Error: /news/today
[Wed Jul 22 15:43:18.631038 2020] [wsgi:error] [pid 845] [remote 221.148.25.236:4217] Traceback (most recent call last):
[Wed Jul 22 15:43:18.631041 2020] [wsgi:error] [pid 845] [remote 221.148.25.236:4217]   File "/home/django/unqocn_venv/lib/python3.8/site-packages/django/core/handlers/exception.py", line 34, in inner
[Wed Jul 22 15:43:18.631044 2020] [wsgi:error] [pid 845] [remote 221.148.25.236:4217]     response = get_response(request)
[Wed Jul 22 15:43:18.631047 2020] [wsgi:error] [pid 845] [remote 221.148.25.236:4217]   File "/home/django/unqocn_venv/lib/python3.8/site-packages/django/utils/deprecation.py", line 93, in __call__
[Wed Jul 22 15:43:18.631050 2020] [wsgi:error] [pid 845] [remote 221.148.25.236:4217]     response = self.process_request(request)
[Wed Jul 22 15:43:18.631053 2020] [wsgi:error] [pid 845] [remote 221.148.25.236:4217]   File "/home/django/unqocn_venv/lib/python3.8/site-packages/django/middleware/common.py", line 54, in process_request
[Wed Jul 22 15:43:18.631055 2020] [wsgi:error] [pid 845] [remote 221.148.25.236:4217]     path = self.get_full_path_with_slash(request)
[Wed Jul 22 15:43:18.631058 2020] [wsgi:error] [pid 845] [remote 221.148.25.236:4217]   File "/home/django/unqocn_venv/lib/python3.8/site-packages/django/middleware/common.py", line 87, in get_full_path_with_slash
[Wed Jul 22 15:43:18.631061 2020] [wsgi:error] [pid 845] [remote 221.148.25.236:4217]     raise RuntimeError(
[Wed Jul 22 15:43:18.631064 2020] [wsgi:error] [pid 845] [remote 221.148.25.236:4217] RuntimeError: You called this URL via POST, but the URL doesn't end in a slash and you have APPEND_SLASH set. Django can't redirect to the slash URL while maintaining POST data. Change your form to point to unqocn-api.hopto.org/news/today/ (note the trailing slash), or set APPEND_SLASH=False in your Django settings.
[Wed Jul 22 15:43:28.941903 2020] [wsgi:error] [pid 845] [remote 221.148.25.236:4224] Internal Server Error: /news/today
[Wed Jul 22 15:43:28.941926 2020] [wsgi:error] [pid 845] [remote 221.148.25.236:4224] Traceback (most recent call last):
[Wed Jul 22 15:43:28.941930 2020] [wsgi:error] [pid 845] [remote 221.148.25.236:4224]   File "/home/django/unqocn_venv/lib/python3.8/site-packages/django/core/handlers/exception.py", line 34, in inner
[Wed Jul 22 15:43:28.941933 2020] [wsgi:error] [pid 845] [remote 221.148.25.236:4224]     response = get_response(request)
[Wed Jul 22 15:43:28.941935 2020] [wsgi:error] [pid 845] [remote 221.148.25.236:4224]   File "/home/django/unqocn_venv/lib/python3.8/site-packages/django/utils/deprecation.py", line 93, in __call__
[Wed Jul 22 15:43:28.941938 2020] [wsgi:error] [pid 845] [remote 221.148.25.236:4224]     response = self.process_request(request)
[Wed Jul 22 15:43:28.941941 2020] [wsgi:error] [pid 845] [remote 221.148.25.236:4224]   File "/home/django/unqocn_venv/lib/python3.8/site-packages/django/middleware/common.py", line 54, in process_request
[Wed Jul 22 15:43:28.941944 2020] [wsgi:error] [pid 845] [remote 221.148.25.236:4224]     path = self.get_full_path_with_slash(request)
[Wed Jul 22 15:43:28.941946 2020] [wsgi:error] [pid 845] [remote 221.148.25.236:4224]   File "/home/django/unqocn_venv/lib/python3.8/site-packages/django/middleware/common.py", line 87, in get_full_path_with_slash
[Wed Jul 22 15:43:28.941949 2020] [wsgi:error] [pid 845] [remote 221.148.25.236:4224]     raise RuntimeError(
[Wed Jul 22 15:43:28.941959 2020] [wsgi:error] [pid 845] [remote 221.148.25.236:4224] RuntimeError: You called this URL via POST, but the URL doesn't end in a slash and you have APPEND_SLASH set. Django can't redirect to the slash URL while maintaining POST data. Change your form to point to unqocn-api.hopto.org/news/today/ (note the trailing slash), or set APPEND_SLASH=False in your Django settings.
[Wed Jul 22 15:43:47.118010 2020] [wsgi:error] [pid 845] [remote 221.148.25.236:4234] Internal Server Error: /news/today
[Wed Jul 22 15:43:47.118034 2020] [wsgi:error] [pid 845] [remote 221.148.25.236:4234] Traceback (most recent call last):
[Wed Jul 22 15:43:47.118037 2020] [wsgi:error] [pid 845] [remote 221.148.25.236:4234]   File "/home/django/unqocn_venv/lib/python3.8/site-packages/django/core/handlers/exception.py", line 34, in inner
[Wed Jul 22 15:43:47.118040 2020] [wsgi:error] [pid 845] [remote 221.148.25.236:4234]     response = get_response(request)
[Wed Jul 22 15:43:47.118042 2020] [wsgi:error] [pid 845] [remote 221.148.25.236:4234]   File "/home/django/unqocn_venv/lib/python3.8/site-packages/django/utils/deprecation.py", line 93, in __call__
[Wed Jul 22 15:43:47.118045 2020] [wsgi:error] [pid 845] [remote 221.148.25.236:4234]     response = self.process_request(request)
[Wed Jul 22 15:43:47.118047 2020] [wsgi:error] [pid 845] [remote 221.148.25.236:4234]   File "/home/django/unqocn_venv/lib/python3.8/site-packages/django/middleware/common.py", line 54, in process_request
[Wed Jul 22 15:43:47.118050 2020] [wsgi:error] [pid 845] [remote 221.148.25.236:4234]     path = self.get_full_path_with_slash(request)
[Wed Jul 22 15:43:47.118052 2020] [wsgi:error] [pid 845] [remote 221.148.25.236:4234]   File "/home/django/unqocn_venv/lib/python3.8/site-packages/django/middleware/common.py", line 87, in get_full_path_with_slash
[Wed Jul 22 15:43:47.118055 2020] [wsgi:error] [pid 845] [remote 221.148.25.236:4234]     raise RuntimeError(
[Wed Jul 22 15:43:47.118057 2020] [wsgi:error] [pid 845] [remote 221.148.25.236:4234] RuntimeError: You called this URL via POST, but the URL doesn't end in a slash and you have APPEND_SLASH set. Django can't redirect to the slash URL while maintaining POST data. Change your form to point to unqocn-api.hopto.org/news/today/ (note the trailing slash), or set APPEND_SLASH=False in your Django settings.
[Wed Jul 22 15:43:58.893478 2020] [wsgi:error] [pid 845] [remote 221.148.25.236:4247] Internal Server Error: /news/today
[Wed Jul 22 15:43:58.893504 2020] [wsgi:error] [pid 845] [remote 221.148.25.236:4247] Traceback (most recent call last):
[Wed Jul 22 15:43:58.893507 2020] [wsgi:error] [pid 845] [remote 221.148.25.236:4247]   File "/home/django/unqocn_venv/lib/python3.8/site-packages/django/core/handlers/exception.py", line 34, in inner
[Wed Jul 22 15:43:58.893510 2020] [wsgi:error] [pid 845] [remote 221.148.25.236:4247]     response = get_response(request)
[Wed Jul 22 15:43:58.893513 2020] [wsgi:error] [pid 845] [remote 221.148.25.236:4247]   File "/home/django/unqocn_venv/lib/python3.8/site-packages/django/utils/deprecation.py", line 93, in __call__
[Wed Jul 22 15:43:58.893516 2020] [wsgi:error] [pid 845] [remote 221.148.25.236:4247]     response = self.process_request(request)
[Wed Jul 22 15:43:58.893519 2020] [wsgi:error] [pid 845] [remote 221.148.25.236:4247]   File "/home/django/unqocn_venv/lib/python3.8/site-packages/django/middleware/common.py", line 54, in process_request
[Wed Jul 22 15:43:58.893521 2020] [wsgi:error] [pid 845] [remote 221.148.25.236:4247]     path = self.get_full_path_with_slash(request)
[Wed Jul 22 15:43:58.893524 2020] [wsgi:error] [pid 845] [remote 221.148.25.236:4247]   File "/home/django/unqocn_venv/lib/python3.8/site-packages/django/middleware/common.py", line 87, in get_full_path_with_slash
[Wed Jul 22 15:43:58.893527 2020] [wsgi:error] [pid 845] [remote 221.148.25.236:4247]     raise RuntimeError(
[Wed Jul 22 15:43:58.893530 2020] [wsgi:error] [pid 845] [remote 221.148.25.236:4247] RuntimeError: You called this URL via POST, but the URL doesn't end in a slash and you have APPEND_SLASH set. Django can't redirect to the slash URL while maintaining POST data. Change your form to point to unqocn-api.hopto.org/news/today/ (note the trailing slash), or set APPEND_SLASH=False in your Django settings.
[Wed Jul 22 15:44:13.776538 2020] [wsgi:error] [pid 845] [remote 221.148.25.236:4256] Internal Server Error: /news/today
[Wed Jul 22 15:44:13.776563 2020] [wsgi:error] [pid 845] [remote 221.148.25.236:4256] Traceback (most recent call last):
[Wed Jul 22 15:44:13.776566 2020] [wsgi:error] [pid 845] [remote 221.148.25.236:4256]   File "/home/django/unqocn_venv/lib/python3.8/site-packages/django/core/handlers/exception.py", line 34, in inner
[Wed Jul 22 15:44:13.776568 2020] [wsgi:error] [pid 845] [remote 221.148.25.236:4256]     response = get_response(request)
[Wed Jul 22 15:44:13.776571 2020] [wsgi:error] [pid 845] [remote 221.148.25.236:4256]   File "/home/django/unqocn_venv/lib/python3.8/site-packages/django/utils/deprecation.py", line 93, in __call__
[Wed Jul 22 15:44:13.776573 2020] [wsgi:error] [pid 845] [remote 221.148.25.236:4256]     response = self.process_request(request)
[Wed Jul 22 15:44:13.776576 2020] [wsgi:error] [pid 845] [remote 221.148.25.236:4256]   File "/home/django/unqocn_venv/lib/python3.8/site-packages/django/middleware/common.py", line 54, in process_request
[Wed Jul 22 15:44:13.776578 2020] [wsgi:error] [pid 845] [remote 221.148.25.236:4256]     path = self.get_full_path_with_slash(request)
[Wed Jul 22 15:44:13.776581 2020] [wsgi:error] [pid 845] [remote 221.148.25.236:4256]   File "/home/django/unqocn_venv/lib/python3.8/site-packages/django/middleware/common.py", line 87, in get_full_path_with_slash
[Wed Jul 22 15:44:13.776583 2020] [wsgi:error] [pid 845] [remote 221.148.25.236:4256]     raise RuntimeError(
[Wed Jul 22 15:44:13.776586 2020] [wsgi:error] [pid 845] [remote 221.148.25.236:4256] RuntimeError: You called this URL via POST, but the URL doesn't end in a slash and you have APPEND_SLASH set. Django can't redirect to the slash URL while maintaining POST data. Change your form to point to unqocn-api.hopto.org/news/today/ (note the trailing slash), or set APPEND_SLASH=False in your Django settings.
[Wed Jul 22 15:58:25.157546 2020] [wsgi:error] [pid 845] [remote 221.148.25.236:4724] Internal Server Error: /news/today
[Wed Jul 22 15:58:25.157573 2020] [wsgi:error] [pid 845] [remote 221.148.25.236:4724] Traceback (most recent call last):
[Wed Jul 22 15:58:25.157577 2020] [wsgi:error] [pid 845] [remote 221.148.25.236:4724]   File "/home/django/unqocn_venv/lib/python3.8/site-packages/django/core/handlers/exception.py", line 34, in inner
[Wed Jul 22 15:58:25.157580 2020] [wsgi:error] [pid 845] [remote 221.148.25.236:4724]     response = get_response(request)
[Wed Jul 22 15:58:25.157582 2020] [wsgi:error] [pid 845] [remote 221.148.25.236:4724]   File "/home/django/unqocn_venv/lib/python3.8/site-packages/django/utils/deprecation.py", line 93, in __call__
[Wed Jul 22 15:58:25.157585 2020] [wsgi:error] [pid 845] [remote 221.148.25.236:4724]     response = self.process_request(request)
[Wed Jul 22 15:58:25.157588 2020] [wsgi:error] [pid 845] [remote 221.148.25.236:4724]   File "/home/django/unqocn_venv/lib/python3.8/site-packages/django/middleware/common.py", line 54, in process_request
[Wed Jul 22 15:58:25.157591 2020] [wsgi:error] [pid 845] [remote 221.148.25.236:4724]     path = self.get_full_path_with_slash(request)
[Wed Jul 22 15:58:25.157593 2020] [wsgi:error] [pid 845] [remote 221.148.25.236:4724]   File "/home/django/unqocn_venv/lib/python3.8/site-packages/django/middleware/common.py", line 87, in get_full_path_with_slash
[Wed Jul 22 15:58:25.157596 2020] [wsgi:error] [pid 845] [remote 221.148.25.236:4724]     raise RuntimeError(
[Wed Jul 22 15:58:25.157599 2020] [wsgi:error] [pid 845] [remote 221.148.25.236:4724] RuntimeError: You called this URL via POST, but the URL doesn't end in a slash and you have APPEND_SLASH set. Django can't redirect to the slash URL while maintaining POST data. Change your form to point to unqocn-api.hopto.org/news/today/ (note the trailing slash), or set APPEND_SLASH=False in your Django settings.
[Wed Jul 22 17:02:34.076341 2020] [wsgi:error] [pid 845] [remote 128.14.134.134:41086] Not Found: /
[Wed Jul 22 18:52:31.438354 2020] [wsgi:error] [pid 845] [remote 117.111.26.16:50712] Not Found: /
[Wed Jul 22 18:52:31.751477 2020] [wsgi:error] [pid 845] [remote 117.111.26.16:50712] Not Found: /favicon.ico
[Wed Jul 22 19:17:29.107439 2020] [wsgi:error] [pid 845] [remote 83.97.20.29:55375] Not Found: /
[Wed Jul 22 19:28:06.934752 2020] [wsgi:error] [pid 845] [remote 93.174.93.139:33716] Not Found: /
[Wed Jul 22 19:56:55.640482 2020] [wsgi:error] [pid 845] [remote 193.118.55.146:57666] Not Found: /
[Wed Jul 22 20:24:41.476245 2020] [wsgi:error] [pid 855] [remote 80.82.70.187:33497] Not Found: /cache/global/img/gs.gif
