[Tue Jul 21 20:27:29.214297 2020] [wsgi:error] [pid 14805] [remote 175.193.7.139:10737] Not Found: /index.php
[Tue Jul 21 20:27:40.648532 2020] [wsgi:error] [pid 14805] [remote 175.193.7.139:10736] Not Found: /index.php
[Tue Jul 21 20:27:46.878884 2020] [wsgi:error] [pid 14805] [remote 175.193.7.139:10743] Not Found: /index.php
[Tue Jul 21 20:39:47.680022 2020] [wsgi:error] [pid 14805] [remote 175.193.7.139:11131] Not Found: /index.php
Exception ignored in: <function BaseEventLoop.__del__ at 0x7f0bbbab5670>
Traceback (most recent call last):
  File "/usr/lib/python3.8/asyncio/base_events.py", line 654, in __del__
NameError: name 'ResourceWarning' is not defined
Exception ignored in: <function Local.__del__ at 0x7f0bc0702700>
Traceback (most recent call last):
  File "/home/django/unqocn_venv/lib/python3.8/site-packages/asgiref/local.py", line 96, in __del__
NameError: name 'TypeError' is not defined
Exception ignored in: <function Local.__del__ at 0x7f0bc0702700>
Traceback (most recent call last):
  File "/home/django/unqocn_venv/lib/python3.8/site-packages/asgiref/local.py", line 96, in __del__
NameError: name 'TypeError' is not defined
Exception ignored in: <function Local.__del__ at 0x7f0bc0702700>
Traceback (most recent call last):
  File "/home/django/unqocn_venv/lib/python3.8/site-packages/asgiref/local.py", line 96, in __del__
NameError: name 'TypeError' is not defined
[Tue Jul 21 20:45:15.115553 2020] [wsgi:error] [pid 15466] [remote 65.154.226.109:16850] Not Found: /
Exception ignored in: <function Local.__del__ at 0x7f0bc080f700>
Traceback (most recent call last):
  File "/home/django/unqocn_venv/lib/python3.8/site-packages/asgiref/local.py", line 96, in __del__
NameError: name 'TypeError' is not defined
Exception ignored in: <function Local.__del__ at 0x7f0bc080f700>
Traceback (most recent call last):
  File "/home/django/unqocn_venv/lib/python3.8/site-packages/asgiref/local.py", line 96, in __del__
NameError: name 'TypeError' is not defined
[Tue Jul 21 20:46:22.849857 2020] [wsgi:error] [pid 15578] [remote 65.154.226.109:39943] Not Found: /
Exception ignored in: <function Local.__del__ at 0x7f0bc080f700>
Traceback (most recent call last):
  File "/home/django/unqocn_venv/lib/python3.8/site-packages/asgiref/local.py", line 96, in __del__
NameError: name 'TypeError' is not defined
Exception ignored in: <function Local.__del__ at 0x7f0bc080f700>
Traceback (most recent call last):
  File "/home/django/unqocn_venv/lib/python3.8/site-packages/asgiref/local.py", line 96, in __del__
NameError: name 'TypeError' is not defined
[Tue Jul 21 21:00:11.352456 2020] [wsgi:error] [pid 16738] [remote 185.39.11.105:33804] Not Found: /
[Tue Jul 21 21:04:59.572546 2020] [wsgi:error] [pid 16738] [remote 106.251.88.102:6487] Not Found: /
[Tue Jul 21 21:25:16.345691 2020] [php7:error] [pid 18177] [client 106.102.129.119:39508] script '/var/www/html/index.php' not found or unable to stat, referer: https://unqocn-api.hopto.org/
[Tue Jul 21 21:25:20.872665 2020] [php7:error] [pid 18177] [client 106.102.129.119:39508] script '/var/www/html/index.php' not found or unable to stat, referer: https://unqocn-api.hopto.org/
[Tue Jul 21 21:25:57.225369 2020] [php7:error] [pid 18251] [client 106.102.129.119:6902] script '/var/www/html/index.php' not found or unable to stat, referer: https://unqocn-api.hopto.org/
[Tue Jul 21 21:25:58.864486 2020] [php7:error] [pid 18251] [client 106.102.129.119:6902] script '/var/www/html/index.php' not found or unable to stat
[Tue Jul 21 21:27:41.088340 2020] [wsgi:error] [pid 18448] [remote 106.102.129.119:42660] Not Found: /index.php
[Tue Jul 21 21:27:41.527633 2020] [wsgi:error] [pid 18448] [remote 106.102.129.119:42660] Not Found: /favicon.ico
Exception ignored in: <function Local.__del__ at 0x7f3b391b7700>
Traceback (most recent call last):
  File "/home/django/unqocn_venv/lib/python3.8/site-packages/asgiref/local.py", line 96, in __del__
NameError: name 'TypeError' is not defined
Exception ignored in: <function Local.__del__ at 0x7f3b391b7700>
Traceback (most recent call last):
  File "/home/django/unqocn_venv/lib/python3.8/site-packages/asgiref/local.py", line 96, in __del__
NameError: name 'TypeError' is not defined
[Tue Jul 21 21:28:28.783309 2020] [ssl:warn] [pid 18440] AH01909: unqocn-api.hopto.org:443:0 server certificate does NOT include an ID which matches the server name
[Tue Jul 21 21:28:40.737513 2020] [wsgi:error] [pid 18551] [remote 106.102.129.119:17406] Not Found: /index.php
[Tue Jul 21 21:28:40.962105 2020] [wsgi:error] [pid 18551] [remote 106.102.129.119:17406] Not Found: /favicon.ico
[Tue Jul 21 21:30:01.500841 2020] [wsgi:error] [pid 18551] [remote 185.39.11.105:50016] Not Found: /
Exception ignored in: <function Local.__del__ at 0x7f3b392c4700>
Traceback (most recent call last):
  File "/home/django/unqocn_venv/lib/python3.8/site-packages/asgiref/local.py", line 96, in __del__
NameError: name 'TypeError' is not defined
Exception ignored in: <function Local.__del__ at 0x7f3b392c4700>
Traceback (most recent call last):
  File "/home/django/unqocn_venv/lib/python3.8/site-packages/asgiref/local.py", line 96, in __del__
NameError: name 'TypeError' is not defined
[Tue Jul 21 21:31:01.458762 2020] [wsgi:error] [pid 18751] [remote 106.102.129.119:55352] Not Found: /index.php/login
[Tue Jul 21 21:31:04.838423 2020] [wsgi:error] [pid 18751] [remote 106.102.129.119:55352] Not Found: /index.php
[Tue Jul 21 21:33:35.671112 2020] [wsgi:error] [pid 18751] [remote 106.102.129.119:63477] Not Found: /index.php
Exception ignored in: <function BaseEventLoop.__del__ at 0x7f6952cd9670>
Traceback (most recent call last):
  File "/usr/lib/python3.8/asyncio/base_events.py", line 654, in __del__
NameError: name 'ResourceWarning' is not defined
Exception ignored in: <function Local.__del__ at 0x7f695391e700>
Traceback (most recent call last):
  File "/home/django/unqocn_venv/lib/python3.8/site-packages/asgiref/local.py", line 96, in __del__
NameError: name 'TypeError' is not defined
Exception ignored in: <function Local.__del__ at 0x7f695391e700>
Traceback (most recent call last):
  File "/home/django/unqocn_venv/lib/python3.8/site-packages/asgiref/local.py", line 96, in __del__
NameError: name 'TypeError' is not defined
[Tue Jul 21 21:46:20.438018 2020] [wsgi:error] [pid 19671] [remote 106.102.129.119:48693] Not Found: /
[Tue Jul 21 21:46:20.822827 2020] [wsgi:error] [pid 19671] [remote 106.102.129.119:48693] Not Found: /favicon.ico
[Tue Jul 21 21:54:39.817011 2020] [wsgi:error] [pid 19669] [remote 93.174.93.139:50600] Not Found: /
[Tue Jul 21 22:03:29.635122 2020] [wsgi:error] [pid 19669] [remote 106.102.129.119:27757] Not Found: /index.php
[Tue Jul 21 22:08:43.270958 2020] [wsgi:error] [pid 19669] [remote 93.158.66.48:42370] Not Found: /.git/HEAD
[Tue Jul 21 22:08:44.537059 2020] [wsgi:error] [pid 19669] [remote 93.158.66.48:42538] Not Found: /.git/HEAD
[Tue Jul 21 22:08:46.918306 2020] [wsgi:error] [pid 19669] [remote 93.158.66.43:40428] Not Found: /.git/HEAD
[Tue Jul 21 22:08:48.192798 2020] [wsgi:error] [pid 19669] [remote 93.158.66.43:40656] Not Found: /.git/HEAD
[Tue Jul 21 22:08:48.762212 2020] [wsgi:error] [pid 19669] [remote 93.158.66.45:38826] Not Found: /.git/HEAD
[Tue Jul 21 22:08:50.028841 2020] [wsgi:error] [pid 19669] [remote 93.158.66.45:38994] Not Found: /.git/HEAD
[Tue Jul 21 22:15:15.408395 2020] [wsgi:error] [pid 19669] [remote 93.158.66.49:56048] Not Found: /.git/HEAD
[Tue Jul 21 22:15:16.711332 2020] [wsgi:error] [pid 19669] [remote 93.158.66.49:56266] Not Found: /.git/HEAD
[Tue Jul 21 22:16:20.199181 2020] [wsgi:error] [pid 19669] [remote 93.158.66.43:45010] Not Found: /.git/HEAD
[Tue Jul 21 22:16:21.438287 2020] [wsgi:error] [pid 19669] [remote 93.158.66.43:45468] Not Found: /.git/HEAD
[Tue Jul 21 22:30:38.670447 2020] [wsgi:error] [pid 19669] [remote 62.173.138.154:52951] Not Found: /
[Tue Jul 21 22:52:20.346597 2020] [wsgi:error] [pid 19669] [remote 185.39.11.105:38928] Not Found: /
Exception ignored in: <function BaseEventLoop.__del__ at 0x7f0eef655670>
Traceback (most recent call last):
  File "/usr/lib/python3.8/asyncio/base_events.py", line 654, in __del__
NameError: name 'ResourceWarning' is not defined
Exception ignored in: <function BaseEventLoop.__del__ at 0x7f0eef655670>
Traceback (most recent call last):
  File "/usr/lib/python3.8/asyncio/base_events.py", line 654, in __del__
NameError: name 'ResourceWarning' is not defined
Exception ignored in: <function Local.__del__ at 0x7f0ef429a700>
Traceback (most recent call last):
  File "/home/django/unqocn_venv/lib/python3.8/site-packages/asgiref/local.py", line 96, in __del__
NameError: name 'TypeError' is not defined
Exception ignored in: <function Local.__del__ at 0x7f0ef429a700>
Traceback (most recent call last):
  File "/home/django/unqocn_venv/lib/python3.8/site-packages/asgiref/local.py", line 96, in __del__
NameError: name 'TypeError' is not defined
Exception ignored in: <function Local.__del__ at 0x7f0ef429a700>
Traceback (most recent call last):
  File "/home/django/unqocn_venv/lib/python3.8/site-packages/asgiref/local.py", line 96, in __del__
NameError: name 'TypeError' is not defined
Exception ignored in: <function Local.__del__ at 0x7f0ef429a700>
Traceback (most recent call last):
  File "/home/django/unqocn_venv/lib/python3.8/site-packages/asgiref/local.py", line 96, in __del__
NameError: name 'TypeError' is not defined
Exception ignored in: <function BaseEventLoop.__del__ at 0x7f7601ce0670>
Traceback (most recent call last):
  File "/usr/lib/python3.8/asyncio/base_events.py", line 654, in __del__
NameError: name 'ResourceWarning' is not defined
Exception ignored in: <function Local.__del__ at 0x7f7602925700>
Traceback (most recent call last):
  File "/home/django/unqocn_venv/lib/python3.8/site-packages/asgiref/local.py", line 96, in __del__
NameError: name 'TypeError' is not defined
Exception ignored in: <function Local.__del__ at 0x7f7602925700>
Traceback (most recent call last):
  File "/home/django/unqocn_venv/lib/python3.8/site-packages/asgiref/local.py", line 96, in __del__
NameError: name 'TypeError' is not defined
[Tue Jul 21 23:03:31.138698 2020] [wsgi:error] [pid 2128] [remote 117.111.28.16:31587] Not Found: /
[Tue Jul 21 23:03:31.498904 2020] [wsgi:error] [pid 2128] [remote 117.111.28.16:31587] Not Found: /favicon.ico
Exception ignored in: <function BaseEventLoop.__del__ at 0x7fdc0c11e670>
Traceback (most recent call last):
  File "/usr/lib/python3.8/asyncio/base_events.py", line 654, in __del__
NameError: name 'ResourceWarning' is not defined
Exception ignored in: <function Local.__del__ at 0x7fdc0cd63700>
Traceback (most recent call last):
  File "/home/django/unqocn_venv/lib/python3.8/site-packages/asgiref/local.py", line 96, in __del__
NameError: name 'TypeError' is not defined
Exception ignored in: <function Local.__del__ at 0x7fdc0cd63700>
Traceback (most recent call last):
  File "/home/django/unqocn_venv/lib/python3.8/site-packages/asgiref/local.py", line 96, in __del__
NameError: name 'TypeError' is not defined
Exception ignored in: <function BaseEventLoop.__del__ at 0x7fa662108670>
Traceback (most recent call last):
  File "/usr/lib/python3.8/asyncio/base_events.py", line 654, in __del__
NameError: name 'ResourceWarning' is not defined
Exception ignored in: <function Local.__del__ at 0x7fa662d4d700>
Traceback (most recent call last):
  File "/home/django/unqocn_venv/lib/python3.8/site-packages/asgiref/local.py", line 96, in __del__
NameError: name 'TypeError' is not defined
Exception ignored in: <function Local.__del__ at 0x7fa662d4d700>
Traceback (most recent call last):
  File "/home/django/unqocn_venv/lib/python3.8/site-packages/asgiref/local.py", line 96, in __del__
NameError: name 'TypeError' is not defined
Exception ignored in: <function BaseEventLoop.__del__ at 0x7f264099e670>
Traceback (most recent call last):
  File "/usr/lib/python3.8/asyncio/base_events.py", line 654, in __del__
NameError: name 'ResourceWarning' is not defined
Exception ignored in: <function Local.__del__ at 0x7f26415e3700>
Traceback (most recent call last):
  File "/home/django/unqocn_venv/lib/python3.8/site-packages/asgiref/local.py", line 96, in __del__
NameError: name 'TypeError' is not defined
Exception ignored in: <function Local.__del__ at 0x7f26415e3700>
Traceback (most recent call last):
  File "/home/django/unqocn_venv/lib/python3.8/site-packages/asgiref/local.py", line 96, in __del__
NameError: name 'TypeError' is not defined
[Tue Jul 21 23:17:16.028469 2020] [wsgi:error] [pid 3450] [remote 67.205.165.53:32862] Not Found: /
[Tue Jul 21 23:17:16.242046 2020] [wsgi:error] [pid 3450] [remote 67.205.165.53:32862] Not Found: /
Exception ignored in: <function Local.__del__ at 0x7f26416dc700>
Traceback (most recent call last):
  File "/home/django/unqocn_venv/lib/python3.8/site-packages/asgiref/local.py", line 96, in __del__
NameError: name 'TypeError' is not defined
Exception ignored in: <function Local.__del__ at 0x7f26416dc700>
Traceback (most recent call last):
  File "/home/django/unqocn_venv/lib/python3.8/site-packages/asgiref/local.py", line 96, in __del__
NameError: name 'TypeError' is not defined
[Wed Jul 22 00:01:52.210881 2020] [wsgi:error] [pid 4879] [remote 185.39.11.105:36230] Not Found: /
[Wed Jul 22 00:10:55.235731 2020] [wsgi:error] [pid 4879] [remote 185.39.11.105:32940] Not Found: /
[Wed Jul 22 00:59:01.135592 2020] [wsgi:error] [pid 4881] [remote 80.82.70.187:45115] Not Found: /cache/global/img/gs.gif
[Wed Jul 22 03:32:23.985783 2020] [wsgi:error] [pid 4879] [remote 193.118.53.210:35318] Not Found: /
[Wed Jul 22 04:01:49.895659 2020] [wsgi:error] [pid 4879] [remote 93.174.93.139:55752] Not Found: /
[Wed Jul 22 05:27:15.837233 2020] [wsgi:error] [pid 4879] [remote 185.39.11.105:32872] Not Found: /
[Wed Jul 22 05:47:31.215048 2020] [wsgi:error] [pid 4879] [remote 162.243.128.91:52518] Not Found: /login
[Wed Jul 22 07:04:53.087165 2020] [wsgi:error] [pid 4879] [remote 185.39.11.105:43754] Not Found: /
[Wed Jul 22 08:05:44.352166 2020] [wsgi:error] [pid 4879] [remote 192.35.168.204:53274] Not Found: /
[Wed Jul 22 08:05:45.146211 2020] [wsgi:error] [pid 4879] [remote 192.35.168.204:37872] Not Found: /
[Wed Jul 22 08:28:16.551901 2020] [wsgi:error] [pid 4879] [remote 92.118.161.33:51435] Not Found: /
[Wed Jul 22 10:23:02.954056 2020] [wsgi:error] [pid 4879] [remote 192.168.219.105:2721] Not Found: /etc/intro.asp
[Wed Jul 22 10:23:03.082961 2020] [wsgi:error] [pid 4879] [remote 192.168.219.105:2721] Not Found: /favicon.ico
[Wed Jul 22 10:23:05.726987 2020] [wsgi:error] [pid 4879] [remote 192.168.219.105:2721] Not Found: /
[Wed Jul 22 10:23:11.391928 2020] [wsgi:error] [pid 4881] [remote 192.168.219.105:2731] Not Found: /
[Wed Jul 22 10:23:12.062356 2020] [wsgi:error] [pid 4881] [remote 192.168.219.105:2731] Not Found: /favicon.ico
[Wed Jul 22 10:24:49.041066 2020] [wsgi:error] [pid 4879] [remote 192.168.219.105:2862] Not Found: /
[Wed Jul 22 10:42:02.255639 2020] [wsgi:error] [pid 4881] [remote 80.82.70.187:60650] Not Found: /cache/global/img/gs.gif
[Wed Jul 22 11:13:37.464199 2020] [wsgi:error] [pid 4879] [remote 185.39.11.105:36776] Not Found: /
[Wed Jul 22 12:16:45.683778 2020] [wsgi:error] [pid 4879] [remote 185.39.11.105:56872] Not Found: /
[Wed Jul 22 12:52:53.142012 2020] [wsgi:error] [pid 4879] [remote 216.218.206.69:42416] Not Found: /
Exception ignored in: <function BaseEventLoop.__del__ at 0x7f2640b0e670>
Traceback (most recent call last):
  File "/usr/lib/python3.8/asyncio/base_events.py", line 654, in __del__
NameError: name 'ResourceWarning' is not defined
Exception ignored in: <function Local.__del__ at 0x7f26416dc700>
Traceback (most recent call last):
  File "/home/django/unqocn_venv/lib/python3.8/site-packages/asgiref/local.py", line 96, in __del__
NameError: name 'TypeError' is not defined
Exception ignored in: <function Local.__del__ at 0x7f26416dc700>
Traceback (most recent call last):
  File "/home/django/unqocn_venv/lib/python3.8/site-packages/asgiref/local.py", line 96, in __del__
NameError: name 'TypeError' is not defined
Exception ignored in: <function Local.__del__ at 0x7f26416dc700>
Traceback (most recent call last):
  File "/home/django/unqocn_venv/lib/python3.8/site-packages/asgiref/local.py", line 96, in __del__
NameError: name 'TypeError' is not defined
Exception ignored in: <function Local.__del__ at 0x7f26416dc700>
Traceback (most recent call last):
  File "/home/django/unqocn_venv/lib/python3.8/site-packages/asgiref/local.py", line 96, in __del__
NameError: name 'TypeError' is not defined
Exception ignored in: <function Local.__del__ at 0x7f26416dc700>
Traceback (most recent call last):
  File "/home/django/unqocn_venv/lib/python3.8/site-packages/asgiref/local.py", line 96, in __del__
NameError: name 'TypeError' is not defined
Exception ignored in: <function Local.__del__ at 0x7f2633fa43a0>
Traceback (most recent call last):
  File "/home/django/unqocn_venv/lib/python3.8/site-packages/asgiref/local.py", line 96, in __del__
NameError: name 'TypeError' is not defined
Exception ignored in: <function Local.__del__ at 0x7f2633fa43a0>
Traceback (most recent call last):
  File "/home/django/unqocn_venv/lib/python3.8/site-packages/asgiref/local.py", line 96, in __del__
NameError: name 'TypeError' is not defined
[Wed Jul 22 14:09:01.728152 2020] [wsgi:error] [pid 845] [remote 198.143.133.154:33136] Not Found: /
[Wed Jul 22 15:39:56.648013 2020] [wsgi:error] [pid 845] [remote 221.148.25.236:4076] Internal Server Error: /news/today
[Wed Jul 22 15:39:56.648040 2020] [wsgi:error] [pid 845] [remote 221.148.25.236:4076] Traceback (most recent call last):
[Wed Jul 22 15:39:56.648044 2020] [wsgi:error] [pid 845] [remote 221.148.25.236:4076]   File "/home/django/unqocn_venv/lib/python3.8/site-packages/django/core/handlers/exception.py", line 34, in inner
[Wed Jul 22 15:39:56.648048 2020] [wsgi:error] [pid 845] [remote 221.148.25.236:4076]     response = get_response(request)
[Wed Jul 22 15:39:56.648052 2020] [wsgi:error] [pid 845] [remote 221.148.25.236:4076]   File "/home/django/unqocn_venv/lib/python3.8/site-packages/django/utils/deprecation.py", line 93, in __call__
[Wed Jul 22 15:39:56.648055 2020] [wsgi:error] [pid 845] [remote 221.148.25.236:4076]     response = self.process_request(request)
[Wed Jul 22 15:39:56.648059 2020] [wsgi:error] [pid 845] [remote 221.148.25.236:4076]   File "/home/django/unqocn_venv/lib/python3.8/site-packages/django/middleware/common.py", line 54, in process_request
[Wed Jul 22 15:39:56.648063 2020] [wsgi:error] [pid 845] [remote 221.148.25.236:4076]     path = self.get_full_path_with_slash(request)
[Wed Jul 22 15:39:56.648066 2020] [wsgi:error] [pid 845] [remote 221.148.25.236:4076]   File "/home/django/unqocn_venv/lib/python3.8/site-packages/django/middleware/common.py", line 87, in get_full_path_with_slash
[Wed Jul 22 15:39:56.648070 2020] [wsgi:error] [pid 845] [remote 221.148.25.236:4076]     raise RuntimeError(
[Wed Jul 22 15:39:56.648074 2020] [wsgi:error] [pid 845] [remote 221.148.25.236:4076] RuntimeError: You called this URL via POST, but the URL doesn't end in a slash and you have APPEND_SLASH set. Django can't redirect to the slash URL while maintaining POST data. Change your form to point to unqocn-api.hopto.org/news/today/ (note the trailing slash), or set APPEND_SLASH=False in your Django settings.
[Wed Jul 22 15:40:13.735734 2020] [wsgi:error] [pid 845] [remote 221.148.25.236:4094] Not Found: /favicon.ico
[Wed Jul 22 15:42:02.680783 2020] [wsgi:error] [pid 845] [remote 221.148.25.236:4172] Internal Server Error: /news/today
[Wed Jul 22 15:42:02.680810 2020] [wsgi:error] [pid 845] [remote 221.148.25.236:4172] Traceback (most recent call last):
[Wed Jul 22 15:42:02.680813 2020] [wsgi:error] [pid 845] [remote 221.148.25.236:4172]   File "/home/django/unqocn_venv/lib/python3.8/site-packages/django/core/handlers/exception.py", line 34, in inner
[Wed Jul 22 15:42:02.680816 2020] [wsgi:error] [pid 845] [remote 221.148.25.236:4172]     response = get_response(request)
[Wed Jul 22 15:42:02.680819 2020] [wsgi:error] [pid 845] [remote 221.148.25.236:4172]   File "/home/django/unqocn_venv/lib/python3.8/site-packages/django/utils/deprecation.py", line 93, in __call__
[Wed Jul 22 15:42:02.680822 2020] [wsgi:error] [pid 845] [remote 221.148.25.236:4172]     response = self.process_request(request)
[Wed Jul 22 15:42:02.680824 2020] [wsgi:error] [pid 845] [remote 221.148.25.236:4172]   File "/home/django/unqocn_venv/lib/python3.8/site-packages/django/middleware/common.py", line 54, in process_request
[Wed Jul 22 15:42:02.680836 2020] [wsgi:error] [pid 845] [remote 221.148.25.236:4172]     path = self.get_full_path_with_slash(request)
[Wed Jul 22 15:42:02.680839 2020] [wsgi:error] [pid 845] [remote 221.148.25.236:4172]   File "/home/django/unqocn_venv/lib/python3.8/site-packages/django/middleware/common.py", line 87, in get_full_path_with_slash
[Wed Jul 22 15:42:02.680841 2020] [wsgi:error] [pid 845] [remote 221.148.25.236:4172]     raise RuntimeError(
[Wed Jul 22 15:42:02.680844 2020] [wsgi:error] [pid 845] [remote 221.148.25.236:4172] RuntimeError: You called this URL via POST, but the URL doesn't end in a slash and you have APPEND_SLASH set. Django can't redirect to the slash URL while maintaining POST data. Change your form to point to unqocn-api.hopto.org/news/today/ (note the trailing slash), or set APPEND_SLASH=False in your Django settings.
[Wed Jul 22 15:42:16.487071 2020] [wsgi:error] [pid 845] [remote 221.148.25.236:4180] Internal Server Error: /news/today
[Wed Jul 22 15:42:16.487095 2020] [wsgi:error] [pid 845] [remote 221.148.25.236:4180] Traceback (most recent call last):
[Wed Jul 22 15:42:16.487098 2020] [wsgi:error] [pid 845] [remote 221.148.25.236:4180]   File "/home/django/unqocn_venv/lib/python3.8/site-packages/django/core/handlers/exception.py", line 34, in inner
[Wed Jul 22 15:42:16.487100 2020] [wsgi:error] [pid 845] [remote 221.148.25.236:4180]     response = get_response(request)
[Wed Jul 22 15:42:16.487103 2020] [wsgi:error] [pid 845] [remote 221.148.25.236:4180]   File "/home/django/unqocn_venv/lib/python3.8/site-packages/django/utils/deprecation.py", line 93, in __call__
[Wed Jul 22 15:42:16.487105 2020] [wsgi:error] [pid 845] [remote 221.148.25.236:4180]     response = self.process_request(request)
[Wed Jul 22 15:42:16.487108 2020] [wsgi:error] [pid 845] [remote 221.148.25.236:4180]   File "/home/django/unqocn_venv/lib/python3.8/site-packages/django/middleware/common.py", line 54, in process_request
[Wed Jul 22 15:42:16.487110 2020] [wsgi:error] [pid 845] [remote 221.148.25.236:4180]     path = self.get_full_path_with_slash(request)
[Wed Jul 22 15:42:16.487113 2020] [wsgi:error] [pid 845] [remote 221.148.25.236:4180]   File "/home/django/unqocn_venv/lib/python3.8/site-packages/django/middleware/common.py", line 87, in get_full_path_with_slash
[Wed Jul 22 15:42:16.487115 2020] [wsgi:error] [pid 845] [remote 221.148.25.236:4180]     raise RuntimeError(
[Wed Jul 22 15:42:16.487117 2020] [wsgi:error] [pid 845] [remote 221.148.25.236:4180] RuntimeError: You called this URL via POST, but the URL doesn't end in a slash and you have APPEND_SLASH set. Django can't redirect to the slash URL while maintaining POST data. Change your form to point to unqocn-api.hopto.org/news/today/ (note the trailing slash), or set APPEND_SLASH=False in your Django settings.
[Wed Jul 22 15:42:42.061628 2020] [wsgi:error] [pid 845] [remote 221.148.25.236:4195] Internal Server Error: /news/today
[Wed Jul 22 15:42:42.061654 2020] [wsgi:error] [pid 845] [remote 221.148.25.236:4195] Traceback (most recent call last):
[Wed Jul 22 15:42:42.061657 2020] [wsgi:error] [pid 845] [remote 221.148.25.236:4195]   File "/home/django/unqocn_venv/lib/python3.8/site-packages/django/core/handlers/exception.py", line 34, in inner
[Wed Jul 22 15:42:42.061660 2020] [wsgi:error] [pid 845] [remote 221.148.25.236:4195]     response = get_response(request)
[Wed Jul 22 15:42:42.061663 2020] [wsgi:error] [pid 845] [remote 221.148.25.236:4195]   File "/home/django/unqocn_venv/lib/python3.8/site-packages/django/utils/deprecation.py", line 93, in __call__
[Wed Jul 22 15:42:42.061666 2020] [wsgi:error] [pid 845] [remote 221.148.25.236:4195]     response = self.process_request(request)
[Wed Jul 22 15:42:42.061669 2020] [wsgi:error] [pid 845] [remote 221.148.25.236:4195]   File "/home/django/unqocn_venv/lib/python3.8/site-packages/django/middleware/common.py", line 54, in process_request
[Wed Jul 22 15:42:42.061672 2020] [wsgi:error] [pid 845] [remote 221.148.25.236:4195]     path = self.get_full_path_with_slash(request)
[Wed Jul 22 15:42:42.061683 2020] [wsgi:error] [pid 845] [remote 221.148.25.236:4195]   File "/home/django/unqocn_venv/lib/python3.8/site-packages/django/middleware/common.py", line 87, in get_full_path_with_slash
[Wed Jul 22 15:42:42.061685 2020] [wsgi:error] [pid 845] [remote 221.148.25.236:4195]     raise RuntimeError(
[Wed Jul 22 15:42:42.061688 2020] [wsgi:error] [pid 845] [remote 221.148.25.236:4195] RuntimeError: You called this URL via POST, but the URL doesn't end in a slash and you have APPEND_SLASH set. Django can't redirect to the slash URL while maintaining POST data. Change your form to point to unqocn-api.hopto.org/news/today/ (note the trailing slash), or set APPEND_SLASH=False in your Django settings.
[Wed Jul 22 15:42:53.519656 2020] [wsgi:error] [pid 845] [remote 221.148.25.236:4202] Internal Server Error: /news/today
[Wed Jul 22 15:42:53.519680 2020] [wsgi:error] [pid 845] [remote 221.148.25.236:4202] Traceback (most recent call last):
[Wed Jul 22 15:42:53.519683 2020] [wsgi:error] [pid 845] [remote 221.148.25.236:4202]   File "/home/django/unqocn_venv/lib/python3.8/site-packages/django/core/handlers/exception.py", line 34, in inner
[Wed Jul 22 15:42:53.519685 2020] [wsgi:error] [pid 845] [remote 221.148.25.236:4202]     response = get_response(request)
[Wed Jul 22 15:42:53.519688 2020] [wsgi:error] [pid 845] [remote 221.148.25.236:4202]   File "/home/django/unqocn_venv/lib/python3.8/site-packages/django/utils/deprecation.py", line 93, in __call__
[Wed Jul 22 15:42:53.519690 2020] [wsgi:error] [pid 845] [remote 221.148.25.236:4202]     response = self.process_request(request)
[Wed Jul 22 15:42:53.519693 2020] [wsgi:error] [pid 845] [remote 221.148.25.236:4202]   File "/home/django/unqocn_venv/lib/python3.8/site-packages/django/middleware/common.py", line 54, in process_request
[Wed Jul 22 15:42:53.519695 2020] [wsgi:error] [pid 845] [remote 221.148.25.236:4202]     path = self.get_full_path_with_slash(request)
[Wed Jul 22 15:42:53.519698 2020] [wsgi:error] [pid 845] [remote 221.148.25.236:4202]   File "/home/django/unqocn_venv/lib/python3.8/site-packages/django/middleware/common.py", line 87, in get_full_path_with_slash
[Wed Jul 22 15:42:53.519700 2020] [wsgi:error] [pid 845] [remote 221.148.25.236:4202]     raise RuntimeError(
[Wed Jul 22 15:42:53.519702 2020] [wsgi:error] [pid 845] [remote 221.148.25.236:4202] RuntimeError: You called this URL via POST, but the URL doesn't end in a slash and you have APPEND_SLASH set. Django can't redirect to the slash URL while maintaining POST data. Change your form to point to unqocn-api.hopto.org/news/today/ (note the trailing slash), or set APPEND_SLASH=False in your Django settings.
[Wed Jul 22 15:43:02.431614 2020] [wsgi:error] [pid 845] [remote 221.148.25.236:4207] Internal Server Error: /news/today
[Wed Jul 22 15:43:02.431642 2020] [wsgi:error] [pid 845] [remote 221.148.25.236:4207] Traceback (most recent call last):
[Wed Jul 22 15:43:02.431649 2020] [wsgi:error] [pid 845] [remote 221.148.25.236:4207]   File "/home/django/unqocn_venv/lib/python3.8/site-packages/django/core/handlers/exception.py", line 34, in inner
[Wed Jul 22 15:43:02.431653 2020] [wsgi:error] [pid 845] [remote 221.148.25.236:4207]     response = get_response(request)
[Wed Jul 22 15:43:02.431656 2020] [wsgi:error] [pid 845] [remote 221.148.25.236:4207]   File "/home/django/unqocn_venv/lib/python3.8/site-packages/django/utils/deprecation.py", line 93, in __call__
[Wed Jul 22 15:43:02.431660 2020] [wsgi:error] [pid 845] [remote 221.148.25.236:4207]     response = self.process_request(request)
[Wed Jul 22 15:43:02.431663 2020] [wsgi:error] [pid 845] [remote 221.148.25.236:4207]   File "/home/django/unqocn_venv/lib/python3.8/site-packages/django/middleware/common.py", line 54, in process_request
[Wed Jul 22 15:43:02.431666 2020] [wsgi:error] [pid 845] [remote 221.148.25.236:4207]     path = self.get_full_path_with_slash(request)
[Wed Jul 22 15:43:02.431669 2020] [wsgi:error] [pid 845] [remote 221.148.25.236:4207]   File "/home/django/unqocn_venv/lib/python3.8/site-packages/django/middleware/common.py", line 87, in get_full_path_with_slash
[Wed Jul 22 15:43:02.431679 2020] [wsgi:error] [pid 845] [remote 221.148.25.236:4207]     raise RuntimeError(
[Wed Jul 22 15:43:02.431683 2020] [wsgi:error] [pid 845] [remote 221.148.25.236:4207] RuntimeError: You called this URL via POST, but the URL doesn't end in a slash and you have APPEND_SLASH set. Django can't redirect to the slash URL while maintaining POST data. Change your form to point to unqocn-api.hopto.org/news/today/ (note the trailing slash), or set APPEND_SLASH=False in your Django settings.
[Wed Jul 22 15:43:18.631014 2020] [wsgi:error] [pid 845] [remote 221.148.25.236:4217] Internal Server Error: /news/today
[Wed Jul 22 15:43:18.631038 2020] [wsgi:error] [pid 845] [remote 221.148.25.236:4217] Traceback (most recent call last):
[Wed Jul 22 15:43:18.631041 2020] [wsgi:error] [pid 845] [remote 221.148.25.236:4217]   File "/home/django/unqocn_venv/lib/python3.8/site-packages/django/core/handlers/exception.py", line 34, in inner
[Wed Jul 22 15:43:18.631044 2020] [wsgi:error] [pid 845] [remote 221.148.25.236:4217]     response = get_response(request)
[Wed Jul 22 15:43:18.631047 2020] [wsgi:error] [pid 845] [remote 221.148.25.236:4217]   File "/home/django/unqocn_venv/lib/python3.8/site-packages/django/utils/deprecation.py", line 93, in __call__
[Wed Jul 22 15:43:18.631050 2020] [wsgi:error] [pid 845] [remote 221.148.25.236:4217]     response = self.process_request(request)
[Wed Jul 22 15:43:18.631053 2020] [wsgi:error] [pid 845] [remote 221.148.25.236:4217]   File "/home/django/unqocn_venv/lib/python3.8/site-packages/django/middleware/common.py", line 54, in process_request
[Wed Jul 22 15:43:18.631055 2020] [wsgi:error] [pid 845] [remote 221.148.25.236:4217]     path = self.get_full_path_with_slash(request)
[Wed Jul 22 15:43:18.631058 2020] [wsgi:error] [pid 845] [remote 221.148.25.236:4217]   File "/home/django/unqocn_venv/lib/python3.8/site-packages/django/middleware/common.py", line 87, in get_full_path_with_slash
[Wed Jul 22 15:43:18.631061 2020] [wsgi:error] [pid 845] [remote 221.148.25.236:4217]     raise RuntimeError(
[Wed Jul 22 15:43:18.631064 2020] [wsgi:error] [pid 845] [remote 221.148.25.236:4217] RuntimeError: You called this URL via POST, but the URL doesn't end in a slash and you have APPEND_SLASH set. Django can't redirect to the slash URL while maintaining POST data. Change your form to point to unqocn-api.hopto.org/news/today/ (note the trailing slash), or set APPEND_SLASH=False in your Django settings.
[Wed Jul 22 15:43:28.941903 2020] [wsgi:error] [pid 845] [remote 221.148.25.236:4224] Internal Server Error: /news/today
[Wed Jul 22 15:43:28.941926 2020] [wsgi:error] [pid 845] [remote 221.148.25.236:4224] Traceback (most recent call last):
[Wed Jul 22 15:43:28.941930 2020] [wsgi:error] [pid 845] [remote 221.148.25.236:4224]   File "/home/django/unqocn_venv/lib/python3.8/site-packages/django/core/handlers/exception.py", line 34, in inner
[Wed Jul 22 15:43:28.941933 2020] [wsgi:error] [pid 845] [remote 221.148.25.236:4224]     response = get_response(request)
[Wed Jul 22 15:43:28.941935 2020] [wsgi:error] [pid 845] [remote 221.148.25.236:4224]   File "/home/django/unqocn_venv/lib/python3.8/site-packages/django/utils/deprecation.py", line 93, in __call__
[Wed Jul 22 15:43:28.941938 2020] [wsgi:error] [pid 845] [remote 221.148.25.236:4224]     response = self.process_request(request)
[Wed Jul 22 15:43:28.941941 2020] [wsgi:error] [pid 845] [remote 221.148.25.236:4224]   File "/home/django/unqocn_venv/lib/python3.8/site-packages/django/middleware/common.py", line 54, in process_request
[Wed Jul 22 15:43:28.941944 2020] [wsgi:error] [pid 845] [remote 221.148.25.236:4224]     path = self.get_full_path_with_slash(request)
[Wed Jul 22 15:43:28.941946 2020] [wsgi:error] [pid 845] [remote 221.148.25.236:4224]   File "/home/django/unqocn_venv/lib/python3.8/site-packages/django/middleware/common.py", line 87, in get_full_path_with_slash
[Wed Jul 22 15:43:28.941949 2020] [wsgi:error] [pid 845] [remote 221.148.25.236:4224]     raise RuntimeError(
[Wed Jul 22 15:43:28.941959 2020] [wsgi:error] [pid 845] [remote 221.148.25.236:4224] RuntimeError: You called this URL via POST, but the URL doesn't end in a slash and you have APPEND_SLASH set. Django can't redirect to the slash URL while maintaining POST data. Change your form to point to unqocn-api.hopto.org/news/today/ (note the trailing slash), or set APPEND_SLASH=False in your Django settings.
[Wed Jul 22 15:43:47.118010 2020] [wsgi:error] [pid 845] [remote 221.148.25.236:4234] Internal Server Error: /news/today
[Wed Jul 22 15:43:47.118034 2020] [wsgi:error] [pid 845] [remote 221.148.25.236:4234] Traceback (most recent call last):
[Wed Jul 22 15:43:47.118037 2020] [wsgi:error] [pid 845] [remote 221.148.25.236:4234]   File "/home/django/unqocn_venv/lib/python3.8/site-packages/django/core/handlers/exception.py", line 34, in inner
[Wed Jul 22 15:43:47.118040 2020] [wsgi:error] [pid 845] [remote 221.148.25.236:4234]     response = get_response(request)
[Wed Jul 22 15:43:47.118042 2020] [wsgi:error] [pid 845] [remote 221.148.25.236:4234]   File "/home/django/unqocn_venv/lib/python3.8/site-packages/django/utils/deprecation.py", line 93, in __call__
[Wed Jul 22 15:43:47.118045 2020] [wsgi:error] [pid 845] [remote 221.148.25.236:4234]     response = self.process_request(request)
[Wed Jul 22 15:43:47.118047 2020] [wsgi:error] [pid 845] [remote 221.148.25.236:4234]   File "/home/django/unqocn_venv/lib/python3.8/site-packages/django/middleware/common.py", line 54, in process_request
[Wed Jul 22 15:43:47.118050 2020] [wsgi:error] [pid 845] [remote 221.148.25.236:4234]     path = self.get_full_path_with_slash(request)
[Wed Jul 22 15:43:47.118052 2020] [wsgi:error] [pid 845] [remote 221.148.25.236:4234]   File "/home/django/unqocn_venv/lib/python3.8/site-packages/django/middleware/common.py", line 87, in get_full_path_with_slash
[Wed Jul 22 15:43:47.118055 2020] [wsgi:error] [pid 845] [remote 221.148.25.236:4234]     raise RuntimeError(
[Wed Jul 22 15:43:47.118057 2020] [wsgi:error] [pid 845] [remote 221.148.25.236:4234] RuntimeError: You called this URL via POST, but the URL doesn't end in a slash and you have APPEND_SLASH set. Django can't redirect to the slash URL while maintaining POST data. Change your form to point to unqocn-api.hopto.org/news/today/ (note the trailing slash), or set APPEND_SLASH=False in your Django settings.
[Wed Jul 22 15:43:58.893478 2020] [wsgi:error] [pid 845] [remote 221.148.25.236:4247] Internal Server Error: /news/today
[Wed Jul 22 15:43:58.893504 2020] [wsgi:error] [pid 845] [remote 221.148.25.236:4247] Traceback (most recent call last):
[Wed Jul 22 15:43:58.893507 2020] [wsgi:error] [pid 845] [remote 221.148.25.236:4247]   File "/home/django/unqocn_venv/lib/python3.8/site-packages/django/core/handlers/exception.py", line 34, in inner
[Wed Jul 22 15:43:58.893510 2020] [wsgi:error] [pid 845] [remote 221.148.25.236:4247]     response = get_response(request)
[Wed Jul 22 15:43:58.893513 2020] [wsgi:error] [pid 845] [remote 221.148.25.236:4247]   File "/home/django/unqocn_venv/lib/python3.8/site-packages/django/utils/deprecation.py", line 93, in __call__
[Wed Jul 22 15:43:58.893516 2020] [wsgi:error] [pid 845] [remote 221.148.25.236:4247]     response = self.process_request(request)
[Wed Jul 22 15:43:58.893519 2020] [wsgi:error] [pid 845] [remote 221.148.25.236:4247]   File "/home/django/unqocn_venv/lib/python3.8/site-packages/django/middleware/common.py", line 54, in process_request
[Wed Jul 22 15:43:58.893521 2020] [wsgi:error] [pid 845] [remote 221.148.25.236:4247]     path = self.get_full_path_with_slash(request)
[Wed Jul 22 15:43:58.893524 2020] [wsgi:error] [pid 845] [remote 221.148.25.236:4247]   File "/home/django/unqocn_venv/lib/python3.8/site-packages/django/middleware/common.py", line 87, in get_full_path_with_slash
[Wed Jul 22 15:43:58.893527 2020] [wsgi:error] [pid 845] [remote 221.148.25.236:4247]     raise RuntimeError(
[Wed Jul 22 15:43:58.893530 2020] [wsgi:error] [pid 845] [remote 221.148.25.236:4247] RuntimeError: You called this URL via POST, but the URL doesn't end in a slash and you have APPEND_SLASH set. Django can't redirect to the slash URL while maintaining POST data. Change your form to point to unqocn-api.hopto.org/news/today/ (note the trailing slash), or set APPEND_SLASH=False in your Django settings.
[Wed Jul 22 15:44:13.776538 2020] [wsgi:error] [pid 845] [remote 221.148.25.236:4256] Internal Server Error: /news/today
[Wed Jul 22 15:44:13.776563 2020] [wsgi:error] [pid 845] [remote 221.148.25.236:4256] Traceback (most recent call last):
[Wed Jul 22 15:44:13.776566 2020] [wsgi:error] [pid 845] [remote 221.148.25.236:4256]   File "/home/django/unqocn_venv/lib/python3.8/site-packages/django/core/handlers/exception.py", line 34, in inner
[Wed Jul 22 15:44:13.776568 2020] [wsgi:error] [pid 845] [remote 221.148.25.236:4256]     response = get_response(request)
[Wed Jul 22 15:44:13.776571 2020] [wsgi:error] [pid 845] [remote 221.148.25.236:4256]   File "/home/django/unqocn_venv/lib/python3.8/site-packages/django/utils/deprecation.py", line 93, in __call__
[Wed Jul 22 15:44:13.776573 2020] [wsgi:error] [pid 845] [remote 221.148.25.236:4256]     response = self.process_request(request)
[Wed Jul 22 15:44:13.776576 2020] [wsgi:error] [pid 845] [remote 221.148.25.236:4256]   File "/home/django/unqocn_venv/lib/python3.8/site-packages/django/middleware/common.py", line 54, in process_request
[Wed Jul 22 15:44:13.776578 2020] [wsgi:error] [pid 845] [remote 221.148.25.236:4256]     path = self.get_full_path_with_slash(request)
[Wed Jul 22 15:44:13.776581 2020] [wsgi:error] [pid 845] [remote 221.148.25.236:4256]   File "/home/django/unqocn_venv/lib/python3.8/site-packages/django/middleware/common.py", line 87, in get_full_path_with_slash
[Wed Jul 22 15:44:13.776583 2020] [wsgi:error] [pid 845] [remote 221.148.25.236:4256]     raise RuntimeError(
[Wed Jul 22 15:44:13.776586 2020] [wsgi:error] [pid 845] [remote 221.148.25.236:4256] RuntimeError: You called this URL via POST, but the URL doesn't end in a slash and you have APPEND_SLASH set. Django can't redirect to the slash URL while maintaining POST data. Change your form to point to unqocn-api.hopto.org/news/today/ (note the trailing slash), or set APPEND_SLASH=False in your Django settings.
[Wed Jul 22 15:58:25.157546 2020] [wsgi:error] [pid 845] [remote 221.148.25.236:4724] Internal Server Error: /news/today
[Wed Jul 22 15:58:25.157573 2020] [wsgi:error] [pid 845] [remote 221.148.25.236:4724] Traceback (most recent call last):
[Wed Jul 22 15:58:25.157577 2020] [wsgi:error] [pid 845] [remote 221.148.25.236:4724]   File "/home/django/unqocn_venv/lib/python3.8/site-packages/django/core/handlers/exception.py", line 34, in inner
[Wed Jul 22 15:58:25.157580 2020] [wsgi:error] [pid 845] [remote 221.148.25.236:4724]     response = get_response(request)
[Wed Jul 22 15:58:25.157582 2020] [wsgi:error] [pid 845] [remote 221.148.25.236:4724]   File "/home/django/unqocn_venv/lib/python3.8/site-packages/django/utils/deprecation.py", line 93, in __call__
[Wed Jul 22 15:58:25.157585 2020] [wsgi:error] [pid 845] [remote 221.148.25.236:4724]     response = self.process_request(request)
[Wed Jul 22 15:58:25.157588 2020] [wsgi:error] [pid 845] [remote 221.148.25.236:4724]   File "/home/django/unqocn_venv/lib/python3.8/site-packages/django/middleware/common.py", line 54, in process_request
[Wed Jul 22 15:58:25.157591 2020] [wsgi:error] [pid 845] [remote 221.148.25.236:4724]     path = self.get_full_path_with_slash(request)
[Wed Jul 22 15:58:25.157593 2020] [wsgi:error] [pid 845] [remote 221.148.25.236:4724]   File "/home/django/unqocn_venv/lib/python3.8/site-packages/django/middleware/common.py", line 87, in get_full_path_with_slash
[Wed Jul 22 15:58:25.157596 2020] [wsgi:error] [pid 845] [remote 221.148.25.236:4724]     raise RuntimeError(
[Wed Jul 22 15:58:25.157599 2020] [wsgi:error] [pid 845] [remote 221.148.25.236:4724] RuntimeError: You called this URL via POST, but the URL doesn't end in a slash and you have APPEND_SLASH set. Django can't redirect to the slash URL while maintaining POST data. Change your form to point to unqocn-api.hopto.org/news/today/ (note the trailing slash), or set APPEND_SLASH=False in your Django settings.
[Wed Jul 22 17:02:34.076341 2020] [wsgi:error] [pid 845] [remote 128.14.134.134:41086] Not Found: /
[Wed Jul 22 18:52:31.438354 2020] [wsgi:error] [pid 845] [remote 117.111.26.16:50712] Not Found: /
[Wed Jul 22 18:52:31.751477 2020] [wsgi:error] [pid 845] [remote 117.111.26.16:50712] Not Found: /favicon.ico
[Wed Jul 22 19:17:29.107439 2020] [wsgi:error] [pid 845] [remote 83.97.20.29:55375] Not Found: /
[Wed Jul 22 19:28:06.934752 2020] [wsgi:error] [pid 845] [remote 93.174.93.139:33716] Not Found: /
[Wed Jul 22 19:56:55.640482 2020] [wsgi:error] [pid 845] [remote 193.118.55.146:57666] Not Found: /
[Wed Jul 22 20:24:41.476245 2020] [wsgi:error] [pid 855] [remote 80.82.70.187:33497] Not Found: /cache/global/img/gs.gif
[Wed Jul 22 22:11:23.217478 2020] [wsgi:error] [pid 855] [remote 93.174.95.106:38458] Not Found: /
[Wed Jul 22 22:11:24.369486 2020] [wsgi:error] [pid 855] [remote 93.174.95.106:39074] Not Found: /favicon.ico
[Wed Jul 22 22:13:06.058303 2020] [wsgi:error] [pid 855] [remote 34.76.78.209:13245] Not Found: /
[Wed Jul 22 22:16:01.032078 2020] [wsgi:error] [pid 845] [remote 45.83.67.187:25288] Not Found: /
[Wed Jul 22 22:42:27.159365 2020] [wsgi:error] [pid 845] [remote 192.168.219.103:1614] Not Found: /favicon.ico
[Wed Jul 22 23:07:12.600188 2020] [wsgi:error] [pid 845] [remote 185.39.11.105:35446] Not Found: /
[Wed Jul 22 23:15:38.027265 2020] [wsgi:error] [pid 845] [remote 192.241.230.237:43368] Not Found: /
Exception ignored in: <function BaseEventLoop.__del__ at 0x7f918b21f670>
Traceback (most recent call last):
  File "/usr/lib/python3.8/asyncio/base_events.py", line 654, in __del__
NameError: name 'ResourceWarning' is not defined
Exception ignored in: <function Local.__del__ at 0x7f918be54700>
Traceback (most recent call last):
  File "/home/django/unqocn_venv/lib/python3.8/site-packages/asgiref/local.py", line 96, in __del__
NameError: name 'TypeError' is not defined
Exception ignored in: <function Local.__del__ at 0x7f918be54700>
Traceback (most recent call last):
  File "/home/django/unqocn_venv/lib/python3.8/site-packages/asgiref/local.py", line 96, in __del__
NameError: name 'TypeError' is not defined
Exception ignored in: <function Local.__del__ at 0x7f918be54700>
Traceback (most recent call last):
  File "/home/django/unqocn_venv/lib/python3.8/site-packages/asgiref/local.py", line 96, in __del__
NameError: name 'TypeError' is not defined
Exception ignored in: <function Local.__del__ at 0x7f918be54700>
Traceback (most recent call last):
  File "/home/django/unqocn_venv/lib/python3.8/site-packages/asgiref/local.py", line 96, in __del__
NameError: name 'TypeError' is not defined
Exception ignored in: <function Local.__del__ at 0x7f918be54700>
Traceback (most recent call last):
  File "/home/django/unqocn_venv/lib/python3.8/site-packages/asgiref/local.py", line 96, in __del__
NameError: name 'TypeError' is not defined
Exception ignored in: <function Local.__del__ at 0x7f918a764430>
Traceback (most recent call last):
  File "/home/django/unqocn_venv/lib/python3.8/site-packages/asgiref/local.py", line 96, in __del__
NameError: name 'TypeError' is not defined
Exception ignored in: <function Local.__del__ at 0x7f918a764430>
Traceback (most recent call last):
  File "/home/django/unqocn_venv/lib/python3.8/site-packages/asgiref/local.py", line 96, in __del__
NameError: name 'TypeError' is not defined
[Thu Jul 23 01:18:32.566841 2020] [wsgi:error] [pid 9814] [remote 192.168.219.103:9364] Not Found: /
[Thu Jul 23 05:03:53.654514 2020] [wsgi:error] [pid 9814] [remote 185.39.11.105:49340] Not Found: /
[Thu Jul 23 05:24:09.082132 2020] [wsgi:error] [pid 9814] [remote 192.35.168.245:40594] Not Found: /
[Thu Jul 23 05:24:09.869207 2020] [wsgi:error] [pid 9814] [remote 192.35.168.245:59404] Not Found: /
[Thu Jul 23 06:05:42.795426 2020] [wsgi:error] [pid 9816] [remote 139.162.153.76:46842] Not Found: /
[Thu Jul 23 06:07:40.211691 2020] [wsgi:error] [pid 9816] [remote 80.82.70.187:49884] Not Found: /cache/global/img/gs.gif
[Thu Jul 23 06:59:41.771111 2020] [wsgi:error] [pid 9814] [remote 185.39.11.105:36720] Not Found: /
[Thu Jul 23 07:32:10.665941 2020] [wsgi:error] [pid 9814] [remote 54.252.173.137:33044] Not Found: /recordings/theme/main.css
[Thu Jul 23 09:49:57.242246 2020] [wsgi:error] [pid 9814] [remote 193.118.53.210:46700] Not Found: /
[Thu Jul 23 14:07:54.053985 2020] [wsgi:error] [pid 9814] [remote 51.158.109.172:57342] Not Found: /
[Thu Jul 23 14:09:18.419449 2020] [wsgi:error] [pid 9814] [remote 139.162.113.204:40728] Not Found: /
[Thu Jul 23 15:50:08.295589 2020] [wsgi:error] [pid 9816] [remote 80.82.70.187:60266] Not Found: /cache/global/img/gs.gif
[Thu Jul 23 16:55:49.500133 2020] [wsgi:error] [pid 9814] [remote 142.93.133.65:33204] Not Found: /
[Thu Jul 23 19:03:54.867992 2020] [wsgi:error] [pid 9814] [remote 193.118.53.202:45314] Not Found: /
[Thu Jul 23 20:25:49.490154 2020] [wsgi:error] [pid 9814] [remote 185.39.11.105:39286] Not Found: /
Exception ignored in: <function BaseEventLoop.__del__ at 0x7f918b3a0670>
Traceback (most recent call last):
  File "/usr/lib/python3.8/asyncio/base_events.py", line 654, in __del__
NameError: name 'ResourceWarning' is not defined
Exception ignored in: <function Local.__del__ at 0x7f918bf54700>
Traceback (most recent call last):
  File "/home/django/unqocn_venv/lib/python3.8/site-packages/asgiref/local.py", line 96, in __del__
NameError: name 'TypeError' is not defined
Exception ignored in: <function Local.__del__ at 0x7f918bf54700>
Traceback (most recent call last):
  File "/home/django/unqocn_venv/lib/python3.8/site-packages/asgiref/local.py", line 96, in __del__
NameError: name 'TypeError' is not defined
Exception ignored in: <function Local.__del__ at 0x7f918bf54700>
Traceback (most recent call last):
  File "/home/django/unqocn_venv/lib/python3.8/site-packages/asgiref/local.py", line 96, in __del__
NameError: name 'TypeError' is not defined
Exception ignored in: <function Local.__del__ at 0x7f918bf54700>
Traceback (most recent call last):
  File "/home/django/unqocn_venv/lib/python3.8/site-packages/asgiref/local.py", line 96, in __del__
NameError: name 'TypeError' is not defined
Exception ignored in: <function Local.__del__ at 0x7f918bf54700>
Traceback (most recent call last):
  File "/home/django/unqocn_venv/lib/python3.8/site-packages/asgiref/local.py", line 96, in __del__
NameError: name 'TypeError' is not defined
Exception ignored in: <function Local.__del__ at 0x7f918a8004c0>
Traceback (most recent call last):
  File "/home/django/unqocn_venv/lib/python3.8/site-packages/asgiref/local.py", line 96, in __del__
NameError: name 'TypeError' is not defined
Exception ignored in: <function Local.__del__ at 0x7f918a8004c0>
Traceback (most recent call last):
  File "/home/django/unqocn_venv/lib/python3.8/site-packages/asgiref/local.py", line 96, in __del__
NameError: name 'TypeError' is not defined
Exception ignored in: <function Local.__del__ at 0x7fc2518f2700>
Traceback (most recent call last):
  File "/home/django/unqocn_venv/lib/python3.8/site-packages/asgiref/local.py", line 96, in __del__
NameError: name 'TypeError' is not defined
Exception ignored in: <function Local.__del__ at 0x7fc2518f2700>
Traceback (most recent call last):
  File "/home/django/unqocn_venv/lib/python3.8/site-packages/asgiref/local.py", line 96, in __del__
NameError: name 'TypeError' is not defined
[Thu Jul 23 21:51:26.980646 2020] [wsgi:error] [pid 44810] [remote 128.14.209.178:49788] Not Found: /
Exception ignored in: <function Local.__del__ at 0x7f5489c1f700>
Traceback (most recent call last):
  File "/home/django/unqocn_venv/lib/python3.8/site-packages/asgiref/local.py", line 96, in __del__
NameError: name 'TypeError' is not defined
Exception ignored in: <function Local.__del__ at 0x7f5489c1f700>
Traceback (most recent call last):
  File "/home/django/unqocn_venv/lib/python3.8/site-packages/asgiref/local.py", line 96, in __del__
NameError: name 'TypeError' is not defined
Exception ignored in: <function Local.__del__ at 0x7f5489c1f700>
Traceback (most recent call last):
  File "/home/django/unqocn_venv/lib/python3.8/site-packages/asgiref/local.py", line 96, in __del__
NameError: name 'TypeError' is not defined
Exception ignored in: <function Local.__del__ at 0x7f5489c1f700>
Traceback (most recent call last):
  File "/home/django/unqocn_venv/lib/python3.8/site-packages/asgiref/local.py", line 96, in __del__
NameError: name 'TypeError' is not defined
[Thu Jul 23 22:46:31.090206 2020] [wsgi:error] [pid 48844] [remote 192.168.219.105:8766] Not Found: /
[Thu Jul 23 22:46:31.239736 2020] [wsgi:error] [pid 48844] [remote 192.168.219.105:8766] Not Found: /favicon.ico
[Thu Jul 23 23:09:47.569856 2020] [wsgi:error] [pid 48846] [remote 185.36.81.37:28500] Not Found: /
Exception ignored in: <function Local.__del__ at 0x7f111c307700>
Traceback (most recent call last):
  File "/home/django/unqocn_venv/lib/python3.8/site-packages/asgiref/local.py", line 96, in __del__
NameError: name 'TypeError' is not defined
Exception ignored in: <function Local.__del__ at 0x7f111c307700>
Traceback (most recent call last):
  File "/home/django/unqocn_venv/lib/python3.8/site-packages/asgiref/local.py", line 96, in __del__
NameError: name 'TypeError' is not defined
Exception ignored in: <function BaseEventLoop.__del__ at 0x7f11176bf670>
Traceback (most recent call last):
  File "/usr/lib/python3.8/asyncio/base_events.py", line 654, in __del__
NameError: name 'ResourceWarning' is not defined
Exception ignored in: <function Local.__del__ at 0x7f111c307700>
Traceback (most recent call last):
  File "/home/django/unqocn_venv/lib/python3.8/site-packages/asgiref/local.py", line 96, in __del__
NameError: name 'TypeError' is not defined
Exception ignored in: <function Local.__del__ at 0x7f111c307700>
Traceback (most recent call last):
  File "/home/django/unqocn_venv/lib/python3.8/site-packages/asgiref/local.py", line 96, in __del__
NameError: name 'TypeError' is not defined
[Fri Jul 24 01:33:46.417458 2020] [wsgi:error] [pid 851] [remote 80.82.70.187:36623] Not Found: /cache/global/img/gs.gif
[Fri Jul 24 02:11:10.947581 2020] [wsgi:error] [pid 849] [remote 128.14.209.234:37440] Not Found: /
[Fri Jul 24 04:59:34.643081 2020] [wsgi:error] [pid 849] [remote 185.39.11.105:39052] Not Found: /
[Fri Jul 24 05:19:26.814338 2020] [wsgi:error] [pid 849] [remote 193.118.53.202:38902] Not Found: /
[Fri Jul 24 05:42:41.436097 2020] [wsgi:error] [pid 849] [remote 83.97.20.29:39817] Not Found: /
[Fri Jul 24 06:10:17.790364 2020] [wsgi:error] [pid 851] [remote 139.162.79.87:45894] Not Found: /
[Fri Jul 24 06:31:39.983473 2020] [wsgi:error] [pid 849] [remote 185.39.11.105:56212] Not Found: /
[Fri Jul 24 08:42:06.740808 2020] [wsgi:error] [pid 849] [remote 195.54.160.21:52022] Not Found: /vendor/phpunit/phpunit/src/Util/PHP/eval-stdin.php
[Fri Jul 24 08:42:06.743526 2020] [wsgi:error] [pid 849] [remote 195.54.160.21:52024] Not Found: /api/jsonws/invoke
[Fri Jul 24 08:42:08.407384 2020] [wsgi:error] [pid 849] [remote 195.54.160.21:49984] Not Found: /vendor/phpunit/phpunit/src/Util/PHP/eval-stdin.php
[Fri Jul 24 08:42:08.408294 2020] [wsgi:error] [pid 849] [remote 195.54.160.21:50398] Not Found: /index.php
[Fri Jul 24 08:42:09.476433 2020] [wsgi:error] [pid 849] [remote 195.54.160.21:48788] Not Found: /
[Fri Jul 24 10:17:35.704451 2020] [wsgi:error] [pid 849] [remote 184.105.247.252:10456] Not Found: /
[Fri Jul 24 11:15:25.165389 2020] [wsgi:error] [pid 851] [remote 80.82.70.187:57126] Not Found: /cache/global/img/gs.gif
[Fri Jul 24 12:30:51.971122 2020] [wsgi:error] [pid 849] [remote 185.39.11.105:45138] Not Found: /
[Fri Jul 24 15:24:03.778946 2020] [wsgi:error] [pid 849] [remote 128.14.209.154:46466] Not Found: /
[Fri Jul 24 16:07:50.415702 2020] [wsgi:error] [pid 849] [remote 128.14.134.134:60496] Not Found: /
[Fri Jul 24 16:26:05.945011 2020] [wsgi:error] [pid 851] [remote 211.36.139.133:10757] Not Found: /favicon.ico
[Fri Jul 24 16:29:01.695194 2020] [wsgi:error] [pid 849] [remote 211.36.139.133:42830] Not Found: /favicon.ico
[Fri Jul 24 19:16:06.990031 2020] [wsgi:error] [pid 849] [remote 185.39.11.105:45204] Not Found: /
[Fri Jul 24 19:55:48.964489 2020] [wsgi:error] [pid 851] [remote 196.52.43.53:52262] Not Found: /
[Fri Jul 24 20:41:14.310629 2020] [wsgi:error] [pid 849] [remote 192.241.239.84:59254] Not Found: /owa/auth/logon.aspx
[Fri Jul 24 20:54:26.237648 2020] [wsgi:error] [pid 851] [remote 80.82.70.187:42333] Not Found: /cache/global/img/gs.gif
[Fri Jul 24 22:22:17.498584 2020] [wsgi:error] [pid 849] [remote 193.118.53.194:36370] Not Found: /
Exception ignored in: <function Local.__del__ at 0x7f9286eed700>
Traceback (most recent call last):
  File "/home/django/unqocn_venv/lib/python3.8/site-packages/asgiref/local.py", line 96, in __del__
NameError: name 'TypeError' is not defined
Exception ignored in: <function Local.__del__ at 0x7f9286eed700>
Traceback (most recent call last):
  File "/home/django/unqocn_venv/lib/python3.8/site-packages/asgiref/local.py", line 96, in __del__
NameError: name 'TypeError' is not defined
Exception ignored in: <function Local.__del__ at 0x7f9286eed700>
Traceback (most recent call last):
  File "/home/django/unqocn_venv/lib/python3.8/site-packages/asgiref/local.py", line 96, in __del__
NameError: name 'TypeError' is not defined
Exception ignored in: <function Local.__del__ at 0x7f9286eed700>
Traceback (most recent call last):
  File "/home/django/unqocn_venv/lib/python3.8/site-packages/asgiref/local.py", line 96, in __del__
NameError: name 'TypeError' is not defined
Exception ignored in: <function Local.__del__ at 0x7f9286eed700>
Traceback (most recent call last):
  File "/home/django/unqocn_venv/lib/python3.8/site-packages/asgiref/local.py", line 96, in __del__
NameError: name 'TypeError' is not defined
Exception ignored in: <function Local.__del__ at 0x7f92857ec3a0>
Traceback (most recent call last):
  File "/home/django/unqocn_venv/lib/python3.8/site-packages/asgiref/local.py", line 96, in __del__
NameError: name 'TypeError' is not defined
Exception ignored in: <function Local.__del__ at 0x7f92857ec3a0>
Traceback (most recent call last):
  File "/home/django/unqocn_venv/lib/python3.8/site-packages/asgiref/local.py", line 96, in __del__
NameError: name 'TypeError' is not defined
[Sat Jul 25 00:03:52.386246 2020] [wsgi:error] [pid 41690] [remote 5.8.10.202:37121] Not Found: /
[Sat Jul 25 00:05:47.801844 2020] [wsgi:error] [pid 41692] [remote 183.136.225.44:48580] Not Found: /
[Sat Jul 25 01:22:10.531977 2020] [wsgi:error] [pid 41692] [remote 167.172.39.126:53284] Not Found: /
[Sat Jul 25 01:22:11.448129 2020] [wsgi:error] [pid 41692] [remote 167.172.39.126:53284] Not Found: /favicon.ico
[Sat Jul 25 01:53:00.813841 2020] [wsgi:error] [pid 41692] [remote 167.172.39.126:39946] Not Found: /
[Sat Jul 25 01:53:01.642201 2020] [wsgi:error] [pid 41692] [remote 167.172.39.126:39946] Not Found: /favicon.ico
[Sat Jul 25 02:05:37.432355 2020] [wsgi:error] [pid 41692] [remote 157.245.139.234:39586] Not Found: /
[Sat Jul 25 02:05:37.887767 2020] [wsgi:error] [pid 41692] [remote 157.245.139.234:39586] Not Found: /favicon.ico
[Sat Jul 25 02:17:41.295786 2020] [wsgi:error] [pid 41690] [remote 185.39.11.105:33336] Not Found: /
[Sat Jul 25 03:08:46.159986 2020] [wsgi:error] [pid 41690] [remote 185.39.11.105:53450] Not Found: /
[Sat Jul 25 03:21:53.655349 2020] [wsgi:error] [pid 41690] [remote 185.39.11.105:59778] Not Found: /
[Sat Jul 25 03:25:00.997503 2020] [wsgi:error] [pid 41692] [remote 45.33.50.106:45642] Not Found: /
[Sat Jul 25 03:25:05.617645 2020] [wsgi:error] [pid 41692] [remote 45.33.50.106:45642] Not Found: /favicon.ico
[Sat Jul 25 03:30:08.225610 2020] [wsgi:error] [pid 41692] [remote 167.71.69.246:54946] Not Found: /
[Sat Jul 25 03:30:08.805749 2020] [wsgi:error] [pid 41692] [remote 167.71.69.246:54946] Not Found: /favicon.ico
[Sat Jul 25 05:39:52.243515 2020] [wsgi:error] [pid 41690] [remote 185.39.11.105:60926] Not Found: /
[Sat Jul 25 06:33:02.576012 2020] [wsgi:error] [pid 41692] [remote 80.82.70.187:50714] Not Found: /cache/global/img/gs.gif
[Sat Jul 25 06:48:29.008757 2020] [wsgi:error] [pid 41690] [remote 185.39.11.105:41710] Not Found: /
[Sat Jul 25 08:55:04.553781 2020] [wsgi:error] [pid 41692] [remote 83.97.20.34:20039] Not Found: /
[Sat Jul 25 09:36:24.278139 2020] [wsgi:error] [pid 41692] [remote 195.144.21.56:46148] Not Found: /
[Sat Jul 25 09:36:30.992708 2020] [wsgi:error] [pid 41692] [remote 195.144.21.56:47470] Not Found: /favicon.ico
[Sat Jul 25 12:53:02.274478 2020] [wsgi:error] [pid 41690] [remote 93.174.93.139:38706] Not Found: /
[Sat Jul 25 13:53:09.737528 2020] [wsgi:error] [pid 41692] [remote 54.177.217.122:53568] Not Found: /
[Sat Jul 25 14:21:10.195807 2020] [wsgi:error] [pid 41690] [remote 74.82.47.2:53994] Not Found: /
[Sat Jul 25 16:14:18.830754 2020] [wsgi:error] [pid 41692] [remote 80.82.70.187:40114] Not Found: /cache/global/img/gs.gif
[Sat Jul 25 17:22:57.393008 2020] [wsgi:error] [pid 41690] [remote 83.97.20.29:32004] Not Found: /
[Sat Jul 25 17:52:47.581808 2020] [wsgi:error] [pid 41690] [remote 18.197.188.8:45162] Not Found: /
[Sat Jul 25 18:11:16.513437 2020] [ssl:error] [pid 41802] [client 64.41.200.108:34808] AH02042: rejecting client initiated renegotiation
[Sat Jul 25 18:11:17.589665 2020] [ssl:error] [pid 41693] [client 64.41.200.108:35378] AH02042: rejecting client initiated renegotiation
[Sat Jul 25 20:18:50.996973 2020] [wsgi:error] [pid 41690] [remote 173.212.225.214:55456] Not Found: /
[Sat Jul 25 21:03:22.565838 2020] [wsgi:error] [pid 41690] [remote 185.39.11.105:52460] Not Found: /
[Sat Jul 25 21:12:41.281423 2020] [wsgi:error] [pid 41690] [remote 185.39.11.105:32906] Not Found: /
[Sat Jul 25 21:24:57.015005 2020] [wsgi:error] [pid 41690] [remote 193.118.53.202:52246] Not Found: /
[Sat Jul 25 23:23:30.535119 2020] [wsgi:error] [pid 41690] [remote 45.148.10.158:34646] Not Found: /
Exception ignored in: <function BaseEventLoop.__del__ at 0x7f9286425670>
Traceback (most recent call last):
  File "/usr/lib/python3.8/asyncio/base_events.py", line 654, in __del__
NameError: name 'ResourceWarning' is not defined
Exception ignored in: <function Local.__del__ at 0x7f9286ffd700>
Traceback (most recent call last):
  File "/home/django/unqocn_venv/lib/python3.8/site-packages/asgiref/local.py", line 96, in __del__
NameError: name 'TypeError' is not defined
Exception ignored in: <function Local.__del__ at 0x7f9286ffd700>
Traceback (most recent call last):
  File "/home/django/unqocn_venv/lib/python3.8/site-packages/asgiref/local.py", line 96, in __del__
NameError: name 'TypeError' is not defined
Exception ignored in: <function Local.__del__ at 0x7f9286ffd700>
Traceback (most recent call last):
  File "/home/django/unqocn_venv/lib/python3.8/site-packages/asgiref/local.py", line 96, in __del__
NameError: name 'TypeError' is not defined
Exception ignored in: <function Local.__del__ at 0x7f9286ffd700>
Traceback (most recent call last):
  File "/home/django/unqocn_venv/lib/python3.8/site-packages/asgiref/local.py", line 96, in __del__
NameError: name 'TypeError' is not defined
Exception ignored in: <function Local.__del__ at 0x7f92858e64c0>
Traceback (most recent call last):
  File "/home/django/unqocn_venv/lib/python3.8/site-packages/asgiref/local.py", line 96, in __del__
NameError: name 'TypeError' is not defined
Exception ignored in: <function Local.__del__ at 0x7f92858e64c0>
Traceback (most recent call last):
  File "/home/django/unqocn_venv/lib/python3.8/site-packages/asgiref/local.py", line 96, in __del__
NameError: name 'TypeError' is not defined
[Sun Jul 26 00:51:50.998635 2020] [wsgi:error] [pid 62180] [remote 92.118.160.29:57019] Not Found: /
[Sun Jul 26 01:55:20.695132 2020] [wsgi:error] [pid 62182] [remote 80.82.70.187:59763] Not Found: /cache/global/img/gs.gif
[Sun Jul 26 03:28:28.127612 2020] [wsgi:error] [pid 62182] [remote 92.118.161.1:47707] Not Found: /
[Sun Jul 26 03:32:49.534847 2020] [wsgi:error] [pid 62182] [remote 80.82.65.213:47634] Not Found: /
[Sun Jul 26 03:50:00.122936 2020] [wsgi:error] [pid 62180] [remote 185.39.11.105:58498] Not Found: /
[Sun Jul 26 04:33:55.896609 2020] [wsgi:error] [pid 62180] [remote 185.39.11.105:50324] Not Found: /
[Sun Jul 26 04:50:07.977046 2020] [wsgi:error] [pid 62180] [remote 185.39.11.105:54110] Not Found: /
[Sun Jul 26 06:05:44.376951 2020] [wsgi:error] [pid 62180] [remote 185.39.11.105:51114] Not Found: /
[Sun Jul 26 06:37:45.576550 2020] [wsgi:error] [pid 62180] [remote 185.39.11.105:36870] Not Found: /
[Sun Jul 26 07:53:49.810758 2020] [wsgi:error] [pid 62180] [remote 185.39.11.105:34542] Not Found: /
[Sun Jul 26 08:24:40.753102 2020] [wsgi:error] [pid 62180] [remote 192.35.168.249:36276] Not Found: /
[Sun Jul 26 08:24:41.545947 2020] [wsgi:error] [pid 62180] [remote 192.35.168.249:52936] Not Found: /
[Sun Jul 26 08:54:14.038844 2020] [wsgi:error] [pid 62180] [remote 185.39.11.105:48608] Not Found: /
[Sun Jul 26 09:13:54.620853 2020] [wsgi:error] [pid 62180] [remote 195.54.160.21:38496] Not Found: /api/jsonws/invoke
[Sun Jul 26 09:13:54.640362 2020] [wsgi:error] [pid 62180] [remote 195.54.160.21:38458] Not Found: /
[Sun Jul 26 09:13:55.620891 2020] [wsgi:error] [pid 62180] [remote 195.54.160.21:56630] Not Found: /vendor/phpunit/phpunit/src/Util/PHP/eval-stdin.php
[Sun Jul 26 09:13:55.641589 2020] [wsgi:error] [pid 62180] [remote 195.54.160.21:59660] Not Found: /vendor/phpunit/phpunit/src/Util/PHP/eval-stdin.php
[Sun Jul 26 09:13:56.634007 2020] [wsgi:error] [pid 62180] [remote 195.54.160.21:44956] Not Found: /index.php
[Sun Jul 26 10:09:11.744124 2020] [wsgi:error] [pid 62180] [remote 185.39.11.105:41834] Not Found: /
[Sun Jul 26 10:22:53.312358 2020] [wsgi:error] [pid 62180] [remote 93.174.93.139:60734] Not Found: /
[Sun Jul 26 10:26:04.366402 2020] [wsgi:error] [pid 62180] [remote 184.105.139.67:31038] Not Found: /
[Sun Jul 26 10:54:28.742569 2020] [wsgi:error] [pid 62180] [remote 93.174.93.139:60876] Not Found: /
[Sun Jul 26 11:38:24.952884 2020] [wsgi:error] [pid 62182] [remote 80.82.70.187:48482] Not Found: /cache/global/img/gs.gif
[Sun Jul 26 13:21:02.088031 2020] [wsgi:error] [pid 62180] [remote 128.14.133.58:43406] Not Found: /cgi-bin/config.exp
[Sun Jul 26 15:47:01.977046 2020] [wsgi:error] [pid 62180] [remote 195.54.160.21:35470] Not Found: /
[Sun Jul 26 15:47:01.983879 2020] [wsgi:error] [pid 62180] [remote 195.54.160.21:35482] Not Found: /api/jsonws/invoke
[Sun Jul 26 15:47:03.530419 2020] [wsgi:error] [pid 62180] [remote 195.54.160.21:54676] Not Found: /vendor/phpunit/phpunit/src/Util/PHP/eval-stdin.php
[Sun Jul 26 15:47:03.573993 2020] [wsgi:error] [pid 62180] [remote 195.54.160.21:54948] Not Found: /vendor/phpunit/phpunit/src/Util/PHP/eval-stdin.php
[Sun Jul 26 15:47:05.146185 2020] [wsgi:error] [pid 62180] [remote 195.54.160.21:50228] Not Found: /index.php
[Sun Jul 26 16:45:53.608512 2020] [ssl:error] [pid 62183] [client 64.41.200.105:45198] AH02042: rejecting client initiated renegotiation
[Sun Jul 26 16:45:54.688194 2020] [ssl:error] [pid 65159] [client 64.41.200.105:45782] AH02042: rejecting client initiated renegotiation
[Sun Jul 26 18:52:16.958664 2020] [wsgi:error] [pid 62180] [remote 194.225.50.38:58230] Not Found: /
[Sun Jul 26 20:38:00.638362 2020] [wsgi:error] [pid 62180] [remote 192.35.168.198:59490] Not Found: /
[Sun Jul 26 20:38:01.448146 2020] [wsgi:error] [pid 62180] [remote 192.35.168.198:47402] Not Found: /
[Sun Jul 26 21:19:26.044687 2020] [wsgi:error] [pid 62182] [remote 80.82.70.187:56459] Not Found: /cache/global/img/gs.gif
[Sun Jul 26 23:00:39.773749 2020] [wsgi:error] [pid 62180] [remote 185.39.11.105:57852] Not Found: /
[Sun Jul 26 23:22:56.270754 2020] [wsgi:error] [pid 62180] [remote 93.174.93.139:60676] Not Found: /
[Sun Jul 26 23:44:42.923074 2020] [wsgi:error] [pid 62180] [remote 185.39.11.105:55104] Not Found: /
Exception ignored in: <function Local.__del__ at 0x7f9286ffd700>
Traceback (most recent call last):
  File "/home/django/unqocn_venv/lib/python3.8/site-packages/asgiref/local.py", line 96, in __del__
NameError: name 'TypeError' is not defined
Exception ignored in: <function Local.__del__ at 0x7f9286ffd700>
Traceback (most recent call last):
  File "/home/django/unqocn_venv/lib/python3.8/site-packages/asgiref/local.py", line 96, in __del__
NameError: name 'TypeError' is not defined
Exception ignored in: <function Local.__del__ at 0x7f9286ffd700>
Traceback (most recent call last):
  File "/home/django/unqocn_venv/lib/python3.8/site-packages/asgiref/local.py", line 96, in __del__
NameError: name 'TypeError' is not defined
Exception ignored in: <function Local.__del__ at 0x7f9286ffd700>
Traceback (most recent call last):
  File "/home/django/unqocn_venv/lib/python3.8/site-packages/asgiref/local.py", line 96, in __del__
NameError: name 'TypeError' is not defined
Exception ignored in: <function Local.__del__ at 0x7f92858e73a0>
Traceback (most recent call last):
  File "/home/django/unqocn_venv/lib/python3.8/site-packages/asgiref/local.py", line 96, in __del__
NameError: name 'TypeError' is not defined
Exception ignored in: <function Local.__del__ at 0x7f92858e73a0>
Traceback (most recent call last):
  File "/home/django/unqocn_venv/lib/python3.8/site-packages/asgiref/local.py", line 96, in __del__
NameError: name 'TypeError' is not defined
[Mon Jul 27 00:05:11.997555 2020] [wsgi:error] [pid 82771] [remote 192.241.216.129:59090] Not Found: /
[Mon Jul 27 00:18:06.960457 2020] [wsgi:error] [pid 82771] [remote 185.39.11.105:38282] Not Found: /
[Mon Jul 27 00:49:13.613685 2020] [wsgi:error] [pid 82771] [remote 185.39.11.105:51354] Not Found: /
[Mon Jul 27 02:00:25.222555 2020] [wsgi:error] [pid 82773] [remote 125.212.217.214:47218] Not Found: /
[Mon Jul 27 02:00:25.862860 2020] [wsgi:error] [pid 82773] [remote 125.212.217.214:47414] Not Found: /favicon.ico
[Mon Jul 27 03:45:01.163152 2020] [wsgi:error] [pid 82771] [remote 80.82.77.227:51964] Not Found: /
[Mon Jul 27 03:57:10.073787 2020] [wsgi:error] [pid 82771] [remote 125.64.94.132:51838] Not Found: /
[Mon Jul 27 04:07:42.206312 2020] [wsgi:error] [pid 82771] [remote 213.32.122.82:4697] Not Found: /
[Mon Jul 27 04:27:43.855287 2020] [wsgi:error] [pid 82771] [remote 185.39.11.105:43088] Not Found: /
[Mon Jul 27 05:13:28.864071 2020] [wsgi:error] [pid 82771] [remote 93.174.93.139:46422] Not Found: /
[Mon Jul 27 05:29:01.764070 2020] [wsgi:error] [pid 82771] [remote 87.27.101.20:59788] Not Found: /
[Mon Jul 27 06:37:48.529251 2020] [wsgi:error] [pid 82771] [remote 185.39.11.105:46116] Not Found: /
[Mon Jul 27 06:54:36.713349 2020] [wsgi:error] [pid 82771] [remote 45.56.78.64:36112] Not Found: /x
[Mon Jul 27 07:01:27.523349 2020] [wsgi:error] [pid 82773] [remote 80.82.70.187:51666] Not Found: /cache/global/img/gs.gif
[Mon Jul 27 07:16:27.025758 2020] [wsgi:error] [pid 82771] [remote 185.39.11.105:40036] Not Found: /
[Mon Jul 27 08:07:52.786443 2020] [wsgi:error] [pid 82771] [remote 139.162.113.204:55042] Not Found: /
[Mon Jul 27 09:17:44.031244 2020] [wsgi:error] [pid 82771] [remote 193.118.53.202:43486] Not Found: /
[Mon Jul 27 11:45:41.001273 2020] [wsgi:error] [pid 82773] [remote 185.39.11.105:42710] Not Found: /
[Mon Jul 27 15:20:43.250694 2020] [wsgi:error] [pid 82771] [remote 185.39.11.105:60260] Not Found: /
[Mon Jul 27 16:46:11.625771 2020] [wsgi:error] [pid 82773] [remote 80.82.70.187:45373] Not Found: /cache/global/img/gs.gif
[Mon Jul 27 18:06:39.297960 2020] [wsgi:error] [pid 82771] [remote 183.136.225.44:32740] Not Found: /
[Mon Jul 27 21:38:50.941635 2020] [wsgi:error] [pid 82771] [remote 185.39.11.105:40784] Not Found: /
[Mon Jul 27 22:38:56.720196 2020] [wsgi:error] [pid 82771] [remote 185.39.11.105:42416] Not Found: /
[Mon Jul 27 23:51:42.720472 2020] [wsgi:error] [pid 82771] [remote 185.39.11.105:53878] Not Found: /
Exception ignored in: <function Local.__del__ at 0x7f9286ffd700>
Traceback (most recent call last):
  File "/home/django/unqocn_venv/lib/python3.8/site-packages/asgiref/local.py", line 96, in __del__
NameError: name 'TypeError' is not defined
Exception ignored in: <function Local.__del__ at 0x7f9286ffd700>
Traceback (most recent call last):
  File "/home/django/unqocn_venv/lib/python3.8/site-packages/asgiref/local.py", line 96, in __del__
NameError: name 'TypeError' is not defined
Exception ignored in: <function Local.__del__ at 0x7f9286ffd700>
Traceback (most recent call last):
  File "/home/django/unqocn_venv/lib/python3.8/site-packages/asgiref/local.py", line 96, in __del__
NameError: name 'TypeError' is not defined
Exception ignored in: <function Local.__del__ at 0x7f9286ffd700>
Traceback (most recent call last):
  File "/home/django/unqocn_venv/lib/python3.8/site-packages/asgiref/local.py", line 96, in __del__
NameError: name 'TypeError' is not defined
Exception ignored in: <function Local.__del__ at 0x7f92858e73a0>
Traceback (most recent call last):
  File "/home/django/unqocn_venv/lib/python3.8/site-packages/asgiref/local.py", line 96, in __del__
NameError: name 'TypeError' is not defined
Exception ignored in: <function Local.__del__ at 0x7f92858e73a0>
Traceback (most recent call last):
  File "/home/django/unqocn_venv/lib/python3.8/site-packages/asgiref/local.py", line 96, in __del__
NameError: name 'TypeError' is not defined
[Tue Jul 28 00:47:55.591327 2020] [wsgi:error] [pid 110794] [remote 185.216.140.186:39302] Not Found: /cache/global/img/gs.gif
